Workbook
Name \0: #REF!
Name \01: #REF!
Name \A: #REF!
Name \A1: #REF!
Name \B: #REF!
Name \B: #REF!
Name \c: #REF!
Name \ddefrgfre: #REF!
Name \e: #REF!
Name \I: #REF!
Name \NOTES: #N/A
Name \P: #REF!
Name \P: #REF!
Name \Q: #REF!
Name \Q: #REF!
Name \s: #REF!
Name \v: #REF!
Name \X: #REF!
Name \z: #REF!
Name ________________pl11: 'P&L-Budget 2025'!________________pl11
Name ________________pl11: #N/A
Name _____________pl11: 'P&L-Budget 2025'!_____________pl11
Name _____________pl11: #N/A
Name ____________pl11: 'P&L-Budget 2025'!____________pl11
Name ____________pl11: #N/A
Name ___________pl11: 'P&L-Budget 2025'!___________pl11
Name ___________pl11: #N/A
Name ________ADD1: #REF!
Name ________ADD1: #REF!
Name ________ADD2: #REF!
Name ________ADD2: #REF!
Name ________ANX8: #REF!
Name ________pg3: #REF!
Name ________pg5: #REF!
Name ________pg7: #REF!
Name ________pg9: #REF!
Name ________SS96: #REF!
Name _______ADD1: #REF!
Name _______ADD2: #REF!
Name _______ANX8: #REF!
Name _______COL04: #N/A
Name _______COL07: #N/A
Name _______eva97: #REF!
Name _______eva97: #REF!
Name _______fcf97: #REF!
Name _______fcf97: #REF!
Name _______mva97: #REF!
Name _______pg3: #REF!
Name _______pg3: #REF!
Name _______pg5: #REF!
Name _______pg5: #REF!
Name _______pg7: #REF!
Name _______pg7: #REF!
Name _______pg9: #REF!
Name _______pg9: #REF!
Name _______roe97: #REF!
Name _______SCH1: #REF!
Name _______SCH10: #REF!
Name _______SCH13: #REF!
Name _______SCH3: #REF!

Sheet SSC Recharge Summary
A1: India Shared Services
A2: 45658 | B2: January, 2025 | D2: 1 | E2: =3+1+7 -> 11 | F2: 1 | G2: 30 | H2: 3 | I2: 3 | J2: =1+1 -> 2 | K2: 15 | L2: 17 | M2: 1 | N2: =18+9 -> 27 | O2: =13+13+1 -> 27 | P2: 1 | Q2: 4 | R2: =1+1 -> 2 | S2: =4+3 -> 7 | T2: 1 | U2: =1+1+2 -> 4 | V2: 1 | W2: =1+1 -> 2 | X2: =2+2+3 -> 7 | Y2: =4+2+7 -> 13 | Z2: 4
D3: CMI | E3: CMI | F3: CMI | N3: GCC +Jibe | R3: Germany | T3: 13th Floor
B4: Business Unit Name | C4: Expense Type | D4: Crew Management | E4: Cruise Management | F4: Accounts | G4: Accounts | H4: Admin | I4: Agency Services | J4: Commercial | K4: Consultancy Services | L4: Environmental Compliance | M4: Environmental Compliance | N4: IT | O4: Procurement | P4: Procurement | Q4: Ship Management | R4: Ship Management | S4: Ship Management | T4: Ship Management | U4: Ship Management | V4: Ship Management | W4: Ship Management | X4: Ship Management | Y4: Ship Management | Z4: Ship Management | AA4: Technical Services | AB4: Ship Management | AC4: Ship Management | AD4: Actual
B5: Division Name | D5: Group Marine HR | E5: Miami Ship Management | F5: CMI Accounts Payables | G5: Fleet Accounts | H5: Administration | I5: Agency Hub | J5: Commercial | K5: Fleet Performance | L5: Carbon Emission Services | M5: Other Environmental Compliance | N5: Group IT | O5: Galleymasters | P5: Sourcing | Q5: Antwerp Dry | R5: Goes Dry | S5: Group Operations | T5: Group Shared Service Center | U5: Hamburg Dry | V5: Hong Kong Dry 1 | W5: JV Ardmore | X5: Singapore Dry | Y5: Singapore Tanker 1 | Z5: Singapore Tanker 2 | AA5: AE Technical Services | AB5: Hong Kong Dry 2 | AC5: Hong Kong Dry 3 | AD5: Total
A7: A | B7: PERSONNEL EXPENSES
B8: Salaries & Wages | C8: Fixed | D8: 6313.72 | E8: 16347.8 | F8: 1643.79 | G8: 29043.29 | H8: 2239.97 | I8: 2256.14 | J8: 7056.17 | K8: 39208.36 | L8: 17844.41 | M8: 4645.25 | N8: 36370.33 | O8: 20535.24 | P8: 3422.24 | Q8: 6549.82 | R8: 1316.03 | S8: 14282.4 | T8: 7330.55 | U8: 3505.1 | V8: 1625.39 | W8: 6195.08 | X8: 15528.55 | Y8: 24979.43 | Z8: 4581.77 | AA8: 826.95 | AB8: 0 | AC8: 0 | AD8: =SUM(D8:AA8) -> 273647.78
B9: Provision for Bonus, Leave & Other Employment Costs | C9: Fixed | D9: 483.74 | E9: 1252.5 | F9: 125.94 | G9: 2233.66 | H9: 171.64 | I9: 172.87 | J9: 540.61 | K9: 3055.21 | L9: 653.74 | M9: 170.33 | N9: 2780.99 | O9: 1596.5 | P9: 262.21 | Q9: 434.51 | R9: 81.59 | S9: 1094.27 | T9: 86.89 | U9: 377.45 | V9: 124.52 | W9: 444.51 | X9: 1198.53 | Y9: 1765.18 | Z9: 626.76 | AA9: 30.32 | AB9: 0 | AC9: 0 | AD9: =SUM(D9:AA9) -> 19764.47
B10: Consultants & Contractors | C10: Fixed | D10: 0 | E10: 0 | F10: 0 | G10: 0 | H10: 0 | I10: 0 | J10: 0 | K10: 0 | L10: 0 | M10: -608.36 | N10: 3344.15 | O10: 0 | P10: 0 | Q10: 0 | R10: 0 | S10: 655.35 | T10: 0 | U10: 0 | V10: 0 | W10: 0 | X10: 0 | Y10: 0 | Z10: 0 | AA10: 0 | AB10: 0 | AC10: 0 | AD10: =SUM(D10:AA10) -> 3391.14
B11: Pension Fund & Social Securities | C11: Fixed | D11: 434.26 | E11: 1017.43 | F11: 94.83 | G11: 1814.75 | H11: 130.79 | I11: 131.66 | J11: 474.57 | K11: 2634.98 | L11: 1247.53 | M11: 349.29 | N11: 2369.94 | O11: 1272.76 | P11: 235.76 | Q11: 431.96 | R11: 79.6 | S11: 945.66 | T11: 522.85 | U11: 195.02 | V11: 93.81 | W11: 422.37 | X11: 1027.41 | Y11: 1671.28 | Z11: 235.91 | AA11: 52.55 | AB11: 0 | AC11: 0 | AD11: =SUM(D11:AA11) -> 17886.97
B12: Staff Allowances & Benefits | C12: Fixed | D12: 36.52 | E12: 1445.56 | F12: 43.99 | G12: 1319.61 | H12: 109.52 | I12: 109.52 | J12: 73.03 | K12: 547.64 | L12: 620.65 | M12: 36.52 | N12: 985.74 | O12: 985.76 | P12: 36.52 | Q12: 146.04 | R12: 73.03 | S12: 255.56 | T12: 36.52 | U12: 146.04 | V12: 36.52 | W12: 73.03 | X12: 255.54 | Y12: 474.61 | Z12: 146.04 | AA12: 36.52 | AB12: 0 | AC12: 0 | AD12: =SUM(D12:AA12) -> 8030.03
B13: Medical Expenses | C13: Variable | D13: 0 | E13: 0 | F13: 0 | G13: 0 | H13: 0 | I13: 0 | J13: 0 | K13: 0 | L13: 0 | M13: 0 | N13: 0 | O13: 0 | P13: 0 | Q13: 0 | R13: 0 | S13: 0 | T13: 0 | U13: 0 | V13: 0 | W13: 0 | X13: 0 | Y13: 0 | Z13: 0 | AA13: 0 | AB13: 0 | AC13: 0 | AD13: =SUM(D13:AA13) -> 0
B14: Staff Recruitment / Relocation | C14: Variable | D14: -0.45 | E14: -5.01 | F14: -0.46 | G14: -13.66 | H14: -1.37 | I14: -1.37 | J14: -0.9 | K14: 24.79 | L14: -7.74 | M14: -0.45 | N14: -1.84 | O14: -12.28 | P14: -0.45 | Q14: -1.82 | R14: 9.53 | S14: -3.19 | T14: 348.58 | U14: 8.63 | V14: -0.45 | W14: -0.9 | X14: -3.18 | Y14: 14.96 | Z14: -1.82 | AA14: -0.45 | AB14: 0 | AC14: 0 | AD14: =SUM(D14:AA14) -> 348.7
B15: Staff Functions | C15: Variable | D15: 37.57 | E15: 413.36 | F15: 37.58 | G15: 1127.39 | H15: 112.74 | I15: 112.74 | J15: 75.14 | K15: 563.68 | L15: 638.84 | M15: 37.57 | N15: 1014.7 | O15: 1014.63 | P15: 37.57 | Q15: 150.32 | R15: 75.14 | S15: 263.06 | T15: 37.57 | U15: 150.3 | V15: 37.57 | W15: 75.14 | X15: 263.04 | Y15: 488.53 | Z15: 150.32 | AA15: 37.57 | AB15: 0 | AC15: 0 | AD15: =SUM(D15:AA15) -> 6952.07
B16: Course & Training | C16: Variable | D16: 0 | E16: 0 | F16: 0 | G16: 0 | H16: 0 | I16: 0 | J16: 0 | K16: 0 | L16: 0 | M16: 0 | N16: 1876.8 | O16: 0 | P16: 0 | Q16: 0 | R16: 0 | S16: 0 | T16: 0 | U16: 0 | V16: 0 | W16: 0 | X16: 0 | Y16: 0 | Z16: 0 | AA16: 0 | AB16: 0 | AC16: 0 | AD16: =SUM(D16:AA16) -> 1876.8
B17: Joint Venture Personnel Cost Recharges | C17: Fixed | D17: 0 | E17: 0 | F17: 0 | G17: 0 | H17: 0 | I17: 0 | J17: 0 | K17: 0 | L17: 0 | M17: 0 | N17: 0 | O17: 0 | P17: 0 | Q17: 0 | R17: 0 | S17: 0 | T17: 0 | U17: 0 | V17: 0 | W17: 0 | X17: 0 | Y17: 0 | Z17: 0 | AA17: 0 | AB17: 0 | AC17: 0 | AD17: =SUM(D17:AA17) -> 0
B18: Intra-group Personnel Cost Recharges | C18: Fixed | D18: 0 | E18: 0 | F18: 0 | G18: 0 | H18: 0 | I18: 0 | J18: 0 | K18: 0 | L18: 0 | M18: 0 | N18: 0 | O18: 0 | P18: 0 | Q18: 0 | R18: 0 | S18: 0 | T18: 0 | U18: 0 | V18: 0 | W18: 0 | X18: 0 | Y18: 0 | Z18: 0 | AA18: 0 | AB18: 0 | AC18: 0 | AD18: =SUM(D18:AA18) -> 0
AD19: =SUM(AD8:AD18) -> 331897.96
A20: B | B20: OFFICE EXPENSES
B21: Rent - Depreciation | C21: Fixed | D21: =+working!C8 -> 131.16383 | E21: =+working!D8 -> 1442.8021 | F21: =+working!E8 -> 131.16383 | G21: =+working!F8 -> 3934.9148 | H21: =+working!G8 -> 393.49148 | I21: =+working!H8 -> 393.49148 | J21: =+working!I8 -> 262.32765 | K21: =+working!J8 -> 1967.4574 | ... Z21: =+working!Y8 -> 524.6553 | AA21: 124.36981 | AB21: 0 | AC21: 0 | AD21: =SUM(D21:AA21) -> 24127.35
B22: Rent - Lease Interest | C22: Fixed | D22: 0 | E22: 0 | F22: 0 | G22: 0 | H22: 0 | I22: 0 | J22: 0 | K22: 0 | L22: 0 | M22: 0 | N22: 0 | O22: 0 | P22: 0 | Q22: 0 | R22: 0 | S22: 0 | T22: 0 | U22: 0 | V22: 0 | W22: 0 | X22: 0 | Y22: 0 | Z22: 0 | AA22: 0 | AB22: 0 | AC22: 0 | AD22: =SUM(D22:AA22) -> 0
B23: Rates & Management Fees | C23: Fixed | D23: 15.58 | E23: 171.38 | F23: 15.58 | G23: 467.47 | H23: 46.73 | I23: 46.73 | J23: 31.16 | K23: 384.51 | L23: 264.88 | M23: 15.58 | N23: 420.6 | O23: 420.71 | P23: 0 | Q23: 62.3 | R23: 31.16 | S23: 109.04 | T23: 4098.63 | U23: 62.31 | V23: 15.58 | W23: 31.16 | X23: 109.05 | Y23: 202.53 | Z23: 62.3 | AA23: 15.58 | AB23: 0 | AC23: 0 | AD23: =SUM(D23:AA23) -> 7100.55
B24: Light & Power | C24: Fixed | D24: 5.88 | E24: 64.75 | F24: 5.88 | G24: 176.49 | H24: 17.67 | I24: 17.67 | J24: 11.76 | K24: 88.3 | L24: 100.1 | M24: 5.88 | N24: 158.93 | O24: 158.93 | P24: 0 | Q24: 23.54 | R24: 11.76 | S24: 41.2 | T24: 342.85 | U24: 23.54 | V24: 5.88 | W24: 11.76 | X24: 41.21 | Y24: 76.51 | Z24: 23.54 | AA24: 5.88 | AB24: 0 | AC24: 0 | AD24: =SUM(D24:AA24) -> 1419.91
B25: Office Supplies & Cleaning | C25: Variable | D25: 8.04 | E25: 88.46 | F25: 8.05 | G25: 241.37 | H25: 24.13 | I25: 24.13 | J25: 16.08 | K25: 120.65 | L25: 136.72 | M25: 8.04 | N25: 217.14 | O25: 217.13 | P25: 0 | Q25: 32.17 | R25: 16.08 | S25: 56.29 | T25: 8.04 | U25: 32.15 | V25: 8.04 | W25: 16.08 | X25: 56.28 | Y25: 104.54 | Z25: 32.17 | AA25: 8.04 | AB25: 0 | AC25: 0 | AD25: =SUM(D25:AA25) -> 1479.82
B26: Archive Storage / Warehouse | C26: Fixed | D26: 0.56 | E26: 6.14 | F26: 0.56 | G26: 16.83 | H26: 1.67 | I26: 1.67 | J26: 1.11 | K26: 8.39 | L26: 9.5 | M26: 0.56 | N26: 15.08 | O26: 15.08 | P26: 0 | Q26: 2.23 | R26: 1.11 | S26: 3.9 | T26: 0.56 | U26: 2.23 | V26: 0.56 | W26: 1.11 | X26: 3.9 | Y26: 7.25 | Z26: 2.23 | AA26: 0.56 | AB26: 0 | AC26: 0 | AD26: =SUM(D26:AA26) -> 102.79
B27: Office Repairs & Maintenance | C27: Fixed | D27: 2.76 | E27: 30.36 | F27: 2.76 | G27: 82.73 | H27: 8.28 | I27: 8.28 | J27: 5.52 | K27: 37.92 | L27: 46.87 | M27: 2.76 | N27: 74.49 | O27: 74.49 | P27: 0 | Q27: 11.04 | R27: 5.52 | S27: 19.32 | T27: 2.76 | U27: 11.03 | V27: 2.53 | W27: 5.52 | X27: 19.3 | Y27: 35.87 | Z27: 11.04 | AA27: 2.76 | AB27: 0 | AC27: 0 | AD27: =SUM(D27:AA27) -> 503.91
B28: Intra-group rental cost recharges | C28: Fixed | D28: 61.71 | E28: 678.76 | F28: 61.7 | G28: 1851.08 | H28: 185.12 | I28: 185.12 | J28: 123.42 | K28: 925.58 | L28: 1048.99 | M28: 61.71 | N28: 1666.04 | O28: 1666.05 | P28: 0 | Q28: 246.82 | R28: 123.42 | S28: 431.93 | T28: 61.71 | U28: 246.83 | V28: 61.71 | W28: 123.42 | X28: 431.93 | Y28: 802.16 | Z28: 246.82 | AA28: 61.71 | AB28: 0 | AC28: 0 | AD28: =SUM(D28:AA28) -> 11353.74
AD29: =SUM(AD21:AD28) -> 46088.07
A30: C | B30: ADMINISTRATIVE EXPENSES
B31: IT - Software & Applications | C31: Variable | D31: 42.96 | E31: 472.54 | F31: 42.95 | G31: 1288.59 | H31: 128.87 | I31: 128.87 | J31: 85.93 | K31: 644.36 | L31: 730.26 | M31: 42.96 | N31: 1159.84 | O31: 1159.87 | P31: 42.96 | Q31: 171.84 | R31: 85.93 | S31: 300.71 | T31: 42.96 | U31: 171.84 | V31: 42.96 | W31: 85.93 | X31: 300.68 | Y31: 558.45 | Z31: 171.84 | AA31: 42.96 | AB31: 0 | AC31: 0 | AD31: =SUM(D31:AA31) -> 7947.06
B32: IT - Communications | C32: Variable | D32: 22.55 | E32: 248.14 | F32: 23.57 | G32: 707.2 | H32: 76.75 | I32: 67.66 | J32: 45.1 | K32: 175.33 | L32: 392.97 | M32: 22.55 | N32: 690.99 | O32: 641.24 | P32: -6.96 | Q32: 90.22 | R32: 45.1 | S32: 157.88 | T32: 22.55 | U32: 90.2 | V32: 11.68 | W32: 45.1 | X32: 157.86 | Y32: 293.25 | Z32: 90.22 | AA32: 22.55 | AB32: 0 | AC32: 0 | AD32: =SUM(D32:AA32) -> 4133.7
B33: IT - IT Services | C33: Variable | D33: 3.33 | E33: 36.61 | F33: 3.32 | G33: 99.73 | H33: 9.99 | I33: 9.99 | J33: 6.66 | K33: 9.56 | L33: 56.57 | M33: 3.33 | N33: 459.3 | O33: 89.86 | P33: 0.64 | Q33: 13.32 | R33: 6.66 | S33: 23.3 | T33: 3.33 | U33: 13.32 | V33: 0.64 | W33: 6.66 | X33: 23.3 | Y33: 43.27 | Z33: 13.32 | AA33: 3.33 | AB33: 0 | AC33: 0 | AD33: =SUM(D33:AA33) -> 939.34
B34: IT - Network & Infrastructure Services | C34: Variable | D34: 0 | E34: 0 | F34: 0 | G34: 0 | H34: 0 | I34: 0 | J34: 0 | K34: 0 | L34: 0 | M34: 0 | N34: 0 | O34: 0 | P34: 0 | Q34: 0 | R34: 0 | S34: 0 | T34: 0 | U34: 0 | V34: 0 | W34: 0 | X34: 0 | Y34: 0 | Z34: 0 | AA34: 0 | AB34: 0 | AC34: 0 | AD34: =SUM(D34:AA34) -> 0
B35: Insurance | C35: Fixed | D35: 0.26 | E35: 2.77 | F35: 0.25 | G35: 7.51 | H35: 0.75 | I35: 0.75 | J35: 0.51 | K35: 3.78 | L35: 4.29 | M35: 0.26 | N35: 6.82 | O35: 6.82 | P35: 0 | Q35: 1.01 | R35: 0.51 | S35: 1.76 | T35: 114.91 | U35: 1.02 | V35: 0.26 | W35: 0.51 | X35: 1.77 | Y35: 3.28 | Z35: 1.01 | AA35: 0.26 | AB35: 0 | AC35: 0 | AD35: =SUM(D35:AA35) -> 161.07
B36: Marketing, Branding & Communications | C36: Variable | D36: 0 | E36: 0 | F36: 0 | G36: 0 | H36: 0 | I36: 0 | J36: 0 | K36: 0 | L36: 0 | M36: 0 | N36: 0 | O36: 0 | P36: 0 | Q36: 0 | R36: 0 | S36: 0 | T36: 0 | U36: 0 | V36: 0 | W36: 0 | X36: 0 | Y36: 0 | Z36: 0 | AA36: 0 | AB36: 0 | AC36: 0 | AD36: =SUM(D36:AA36) -> 0
B37: Overseas Travelling | C37: Variable | D37: 2757.23 | E37: 0 | F37: 0 | G37: 0 | H37: 0 | I37: 0 | J37: 0 | K37: 673.8 | L37: 0 | M37: 0 | N37: 0 | O37: 0 | P37: 0 | Q37: 0 | R37: 0 | S37: 0 | T37: 2970.37 | U37: 0 | V37: 384.24 | W37: 0 | X37: 0 | Y37: 62.15 | Z37: 0 | AA37: 0 | AB37: 0 | AC37: 0 | AD37: =SUM(D37:AA37) -> 6847.79
B38: Local Travelling | C38: Variable | D38: 21.39 | E38: 594.86 | F38: 18.25 | G38: 547.57 | H38: 100.96 | I38: 64.17 | J38: 179.19 | K38: 4.94 | L38: 318.94 | M38: 21.39 | N38: 549.07 | O38: 549.08 | P38: 0.01 | Q38: 85.56 | R38: 42.78 | S38: 157.08 | T38: 336.26 | U38: 85.57 | V38: -7.78 | W38: 42.78 | X38: 149.75 | Y38: 278.07 | Z38: 85.56 | AA38: 21.39 | AB38: 0 | AC38: 0 | AD38: =SUM(D38:AA38) -> 4246.84
B39: ISSC Team | C39: Variable | D39: 0 | E39: 0 | F39: 0 | G39: 0 | H39: 0 | I39: 0 | J39: 0 | K39: 0 | L39: 0 | M39: 0 | N39: 0 | O39: 0 | P39: 0 | Q39: 0 | R39: 0 | S39: 0 | T39: 0 | U39: 0 | V39: 0 | W39: 0 | X39: 0 | Y39: 0 | Z39: 0 | AD39: =SUM(D39:AA39) -> 0
B40: Motor Car Expenses | C40: Variable | D40: 198.46 | E40: -138.76 | F40: 2.5 | G40: 74.97 | H40: 0 | I40: 0 | J40: 0 | K40: 0 | L40: 0 | M40: 0 | N40: 0 | O40: 0 | P40: 0 | Q40: 0 | R40: 0 | S40: 0 | T40: 543.23 | U40: 0 | V40: 0 | W40: 0 | X40: 0 | Y40: 0 | Z40: 0 | AA40: 0 | AB40: 0 | AC40: 0 | AD40: =SUM(D40:AA40) -> 680.4
B41: Entertainment | C41: Variable | D41: 0 | E41: 0 | F41: 0 | G41: 0 | H41: 0 | I41: 0 | J41: 0 | K41: 0 | L41: 0 | M41: 0 | N41: 0 | O41: 0 | P41: 0 | Q41: 0 | R41: 0 | S41: 40.53 | T41: 56.99 | U41: 0 | V41: 0 | W41: 0 | X41: 0 | Y41: 0 | Z41: 0 | AA41: 0 | AB41: 0 | AC41: 0 | AD41: =SUM(D41:AA41) -> 97.52
...

Sheet ISSC Spend_KPI's
A1: Category: Overall Cost Insights | F1: 45658 | H1: 45689 | J1: 45717 | K1: 45748 | L1: 45778 | M1: 45809 | N1: 45839 | O1: 45870 | P1: 45901 | Q1: 45931 | R1: 45962 | S1: 45992
A2: KPI | B2: Description | C2: Remark | D2: Formula (Excel) | F2: Total (All BU) | H2: Total (All BU)
D3: Headcount | F3: =+'SSC Recharge Summary'!AD77 -> 185 | H3: =+'SSC Recharge Summary'!AD154 -> 189
A4: 1. Total ISSC Spend | B4: Aggregate spend across all categories | F4: =+'SSC Recharge Summary'!AD72 -> 440161.1 | H4: =+'SSC Recharge Summary'!AD149 -> 448023.2
A5: 2. Spend vs. Budget Variance | B5: Variance between actual spend and the allocated budget ( BU & overall) | C5: Pls add budget provided by ISSC | D5: Actual minus Budget | F5: =+F4-'P&L-Budget 2025'!MB264 -> 1805.5196 | H5: =+H4-'P&L-Budget 2025'!MC264 -> 24303.47
D6: Variance Remarks
A7: 3. Fixed vs. Variable Cost Ratio | B7: Proportion of Fixed costs Vs. Vriable costs | F7: ='SSC Recharge Summary'!AD73&" "&":" &" "&'SSC Recharge Summary'!AD74 -> 0.91 : 0.09 | H7: ='SSC Recharge Summary'!AD150&" "&":" &" "&'SSC Recharge Summary'!AD151 -> 0.94 : 0.06
A8: 4. Cost Per FTE (Desk Cost) | B8: Total SSC cost divided by the number of ISSC HC | F8: =F4/F3 -> 2379.2492 | H8: =+H4/H3 -> 2370.4931
A9: Employee-Related Costs
A10: KPI | B10: Description | D10: Formula (Excel)
A11: 1. Employee Cost as % of Total ISSC Spend | B11: Proportion of overall Employee Cost relative to the total ISSC spend | F11: =SUM('SSC Recharge Summary'!AD8:AD18)/F4 -> 0.75403747 | H11: =SUM('SSC Recharge Summary'!AD101:AD108)/H4 -> 0.7950009
A12: 2. Training Cost per Employee | B12: Total training-related costs divided by the number of ISSC HC trained
A13: IT & Technology Costs
A14: KPI | B14: Description | D14: Formula (Excel)
A15: 1. IT Spend as % of Total ISSC Spend | B15: Proportion of overall IT expenses relative to the total ISSC spend | F15: =SUM('SSC Recharge Summary'!AD31:AD34)/'ISSC Spend_KPI''s'!F4 -> 0.029580306 | H15: =SUM('SSC Recharge Summary'!AD121:AD123)/H4 -> 0.026190496
A16: Facility & Office Costs
A17: KPI | B17: Description | D17: Formula (Excel)
A18: 1. Total Facility Spend | B18: Total rent, utilities, and maintenance costs | F18: =SUM('SSC Recharge Summary'!AD21:AD28) -> 46088.07 | H18: =+'SSC Recharge Summary'!AD119 -> 36724.24
A19: 2. Facility Spend as % of Total Spend | B19: Proportion of overall Facility Spend relative to the total ISSC spend | F19: =F18/F4 -> 0.10470728 | H19: =H18/H4 -> 0.081969505
A20: 3. Average Cost per Employee | B20: Total Facility Spend / Number of Employees | F20: =F18/F3 -> 249.1247 | H20: =+H18/H3 -> 194.30815
A21: 4. Space Utilization | B21: percentage of space that is actively used versus the total available space | C21: Admin
A22: 5. Admin Cost per FTE | B22: Total administrative expenses divided by the number of employees | F22: =SUM('SSC Recharge Summary'!AD35:AD52)/F3 -> 90.414634 | H22: =SUM('SSC Recharge Summary'!AD125:AD139)/H3 -> 66.955771
A23: Travel & Transportation Costs
A24: KPI | B24: Description | D24: Formula (Excel)
A25: 1. Travel Spend per Employee | B25: Total travel-related costs divided by the number of employees who traveled.(Domestic/International) | F25: =SUM('SSC Recharge Summary'!AD37:AD38)/F3 -> 59.970973 | H25: =SUM('SSC Recharge Summary'!AD127:AD128)/H3 -> 48.112593
A26: 2. Overall Travel Cost | F26: =SUM('SSC Recharge Summary'!AD37:AD38) -> 11094.63 | H26: =SUM('SSC Recharge Summary'!AD127:AD128) -> 9093.28
A27: 3.Travel Cost as % of Total ISSC Spend | F27: =F26/F4 -> 0.02520584 | H27: =+H26/H4 -> 0.020296449

Sheet P&L-Budget 2025
B1: ANGLO-EASTERN MARITIME SERVICES PRIVATE LIMITED | P1: =+P11 -> Budget-2025 | AD1: =+AD11 -> Budget-2025 | AR1: =+AR11 -> Budget-2025 | BF1: =+BF11 -> Budget-2025 | BT1: =+BT11 -> #REF! | CH1: =+CH11 -> #REF! | CV1: =+CV11 -> #REF! | DJ1: =+DJ11 -> #REF! | DX1: =+DX11 -> #REF! | EL1: =+EL11 -> #REF! | EZ1: =+EZ11 -> #REF! | FN1: =+FN11 -> #REF! | GB1: =+GB11 -> #REF! | GP1: =+GP11 -> #REF! | HD1: =+HD11 -> Total | HR1: =+HR11 -> #REF! | IF1: =+IF11 -> #REF! | IT1: =+IT11 -> #REF! | JH1: =+JH11 -> #REF! | JV1: =+JV11 -> #REF! | KJ1: =+KJ11 -> #REF! | KX1: =+KX11 -> Total | LL1: =+LL11 -> Total | LZ1: =+LZ11 -> Total | MB1: =+LZ1 -> Total | MC1: =+MB1 -> Total | MD1: =+MC1 -> Total | ME1: =+MD1 -> Total | MF1: =+ME1 -> Total | MG1: =+MF1 -> Total | MH1: =+MG1 -> Total | MI1: =+MH1 -> Total | MJ1: =+MI1 -> Total | ... MN1: =+MM1 -> Total
B2: Budget 2025 | P2: 1 | AD2: 2 | AR2: 3 | BF2: 4 | BT2: 6 | CH2: 8 | CV2: 11 | DJ2: 12 | DX2: 13 | EL2: 14 | EZ2: 15 | FN2: 16 | GB2: 17 | GP2: 19 | HD2: 30 | HR2: 20 | IF2: 21 | IT2: 22 | JH2: 23 | JV2: 24 | KJ2: 25 | KX2: 28 | LL2: 29 | LZ2: 31
B8: BU | D8: Accounts | P8: =+D8 -> Accounts | R8: Admin | AD8: =+R8 -> Admin | AF8: Agency Services | AR8: =AF8 -> Agency Services | AT8: Commercial | BF8: =AT8 -> Commercial | BH8: Consultancy Services | BT8: =+BH8 -> Consultancy Services | BV8: Crew Management | CH8: =+BV8 -> Crew Management | CJ8: Cruise Management | CV8: =+CJ8 -> Cruise Management | CX8: IT | DJ8: =+CX8 -> IT | DL8: Procurement | DX8: =+DL8 -> Procurement | DZ8: Procurement | EL8: =+DZ8 -> Procurement | EN8: Ship Management | EZ8: =+EN8 -> Ship Management | FB8: Ship Management | FN8: =+FB8 -> Ship Management | FP8: Ship Management | GB8: =+FP8 -> Ship Management | GD8: Ship Management | GP8: =+GD8 -> Ship Management | GR8: Vacant Seats | HD8: =+GR8 -> Vacant Seats | HF8: Ship Management | HR8: =+HF8 -> Ship Management | HT8: Ship Management | IF8: =+HT8 -> Ship Management | IH8: Ship Management | IT8: =+IH8 -> Ship Management | IV8: Ship Management | JH8: =+IV8 -> Ship Management | JJ8: Ship Management | JV8: =+JJ8 -> Ship Management | JX8: Ship Management | KJ8: =+JX8 -> Ship Management | KL8: Accounts | KX8: =+KL8 -> Accounts | KZ8: Accounts | LL8: =+KZ8 -> Accounts | LZ8: =+LN8 -> 0 | MB8: =LN11 -> 45688 | MC8: =LO11 -> 45716 | MD8: =LP11 -> 45747 | ME8: =LQ11 -> 45777 | MF8: =LR11 -> 45808 | MG8: =LS11 -> 45838 | MH8: =LT11 -> 45869 | MI8: =LU11 -> 45900 | ... MN8: =LZ11 -> Total
B9: Division | D9: Fleet Accounts | P9: =+D9 -> Fleet Accounts | R9: Administration | AD9: =+R9 -> Administration | AF9: Agency Hub | AR9: =AF9 -> Agency Hub | AT9: Commercial | BF9: =AT9 -> Commercial | BH9: Fleet Performance | BT9: =+BH9 -> Fleet Performance | BV9: Group Marine HR | CH9: =+BV9 -> Group Marine HR | CJ9: Miami Ship Management | CV9: =+CJ9 -> Miami Ship Management | CX9: Group IT | DJ9: =+CX9 -> Group IT | DL9: Galleymasters | DX9: =+DL9 -> Galleymasters | DZ9: Sourcing | EL9: =+DZ9 -> Sourcing | EN9: Antwerp Dry | EZ9: =+EN9 -> Antwerp Dry | FB9: Goes Dry | FN9: =+FB9 -> Goes Dry | FP9: Group Operations | GB9: =+FP9 -> Group Operations | GD9: Group Shared Service Center | GP9: =+GD9 -> Group Shared Service Center | GR9: Vacant Seats | HD9: =+GR9 -> Vacant Seats | HF9: Hamburg Dry | HR9: =+HF9 -> Hamburg Dry | HT9: Hong Kong Dry 1 | IF9: =+HT9 -> Hong Kong Dry 1 | IH9: JV Ardmore | IT9: =+IH9 -> JV Ardmore | IV9: Singapore Dry | JH9: =+IV9 -> Singapore Dry | JJ9: Singapore Tanker 1 | JV9: =+JJ9 -> Singapore Tanker 1 | JX9: Singapore Tanker 2 | KJ9: =+JX9 -> Singapore Tanker 2 | KL9: Accounts Payables | KX9: =+KL9 -> Accounts Payables | KZ9: CMI Accounts Payables | LL9: =+KZ9 -> CMI Accounts Payables | LZ9: =+LN9 -> 0 | MB9: All Divisions | MC9: =MB9 -> All Divisions | MD9: =MC9 -> All Divisions | ME9: =MD9 -> All Divisions | MF9: =ME9 -> All Divisions | MG9: =MF9 -> All Divisions | MH9: =MG9 -> All Divisions | MI9: =MH9 -> All Divisions | MJ9: =MI9 -> All Divisions | ... MN9: =MM9 -> All Divisions
B10: Amount (INR) | D10: INR | E10: INR | F10: INR | G10: INR | H10: INR | I10: INR | J10: INR | K10: INR | L10: INR | M10: INR | N10: INR | O10: INR | P10: INR | R10: INR | S10: INR | T10: INR | U10: INR | V10: INR | W10: INR | X10: INR | Y10: INR | Z10: INR | AA10: INR | AB10: INR | AC10: INR | AD10: INR | AF10: INR | AG10: INR | AH10: INR | AI10: INR | AJ10: INR | AK10: INR | AL10: INR | AM10: INR | AN10: INR | AO10: INR | AP10: INR | AQ10: INR | AR10: INR | AT10: INR | AU10: INR | AV10: INR | AW10: INR | AX10: INR | AY10: INR | AZ10: INR | BA10: INR | BB10: INR | BC10: INR | BD10: INR | BE10: INR | BF10: INR | BH10: INR | BI10: INR | BJ10: INR | BK10: INR | BL10: INR | BM10: INR | BN10: INR | BO10: INR | BP10: INR | BQ10: INR | BR10: INR | BS10: INR | BT10: INR | BV10: INR | BW10: INR | BX10: INR | BY10: INR | BZ10: INR | CA10: INR | CB10: INR | CC10: INR | CD10: INR | CE10: INR | CF10: INR | CG10: INR | CH10: INR | CJ10: INR | CK10: INR | CL10: INR | CM10: INR | CN10: INR | CO10: INR | CP10: INR | CQ10: INR | CR10: INR | CS10: INR | CT10: INR | CU10: INR | CV10: INR | CX10: INR | CY10: INR | CZ10: INR | DA10: INR | DB10: INR | DC10: INR | DD10: INR | DE10: INR | DF10: INR | DG10: INR | DH10: INR | DI10: INR | DJ10: INR | DL10: INR | DM10: INR | DN10: INR | DO10: INR | DP10: INR | DQ10: INR | DR10: INR | DS10: INR | DT10: INR | DU10: INR | DV10: INR | DW10: INR | DX10: INR | DZ10: INR | EA10: INR | EB10: INR | EC10: INR | ED10: INR | EE10: INR | EF10: INR | EG10: INR | EH10: INR | EI10: INR | EJ10: INR | EK10: INR | EL10: INR | EN10: INR | EO10: INR | EP10: INR | EQ10: INR | ER10: INR | ES10: INR | ET10: INR | EU10: INR | EV10: INR | EW10: INR | EX10: INR | EY10: INR | EZ10: INR | FB10: INR | FC10: INR | FD10: INR | FE10: INR | FF10: INR | FG10: INR | FH10: INR | FI10: INR | FJ10: INR | FK10: INR | FL10: INR | FM10: INR | FN10: INR | FP10: INR | FQ10: INR | FR10: INR | FS10: INR | FT10: INR | FU10: INR | FV10: INR | FW10: INR | FX10: INR | FY10: INR | FZ10: INR | GA10: INR | GB10: INR | GD10: INR | GE10: INR | GF10: INR | GG10: INR | GH10: INR | GI10: INR | GJ10: INR | GK10: INR | GL10: INR | GM10: INR | GN10: INR | GO10: INR | GP10: INR | GR10: INR | GS10: INR | GT10: INR | GU10: INR | GV10: INR | GW10: INR | GX10: INR | GY10: INR | GZ10: INR | HA10: INR | HB10: INR | HC10: INR | HD10: INR | HF10: INR | HG10: INR | HH10: INR | HI10: INR | HJ10: INR | HK10: INR | HL10: INR | HM10: INR | HN10: INR | HO10: INR | HP10: INR | HQ10: INR | HR10: INR | HT10: INR | HU10: INR | HV10: INR | HW10: INR | HX10: INR | HY10: INR | HZ10: INR | IA10: INR | IB10: INR | IC10: INR | ID10: INR | IE10: INR | IF10: INR | IH10: INR | II10: INR | IJ10: INR | IK10: INR | IL10: INR | IM10: INR | IN10: INR | IO10: INR | IP10: INR | IQ10: INR | IR10: INR | IS10: INR | IT10: INR | IV10: INR | IW10: INR | IX10: INR | IY10: INR | IZ10: INR | JA10: INR | JB10: INR | JC10: INR | JD10: INR | JE10: INR | JF10: INR | JG10: INR | JH10: INR | JJ10: INR | JK10: INR | JL10: INR | JM10: INR | JN10: INR | JO10: INR | JP10: INR | JQ10: INR | JR10: INR | JS10: INR | JT10: INR | JU10: INR | JV10: INR | JX10: INR | JY10: INR | JZ10: INR | KA10: INR | KB10: INR | KC10: INR | KD10: INR | KE10: INR | KF10: INR | KG10: INR | KH10: INR | KI10: INR | KJ10: INR | KL10: INR | KM10: INR | KN10: INR | KO10: INR | KP10: INR | KQ10: INR | KR10: INR | KS10: INR | KT10: INR | KU10: INR | KV10: INR | KW10: INR | KX10: INR | KZ10: INR | LA10: INR | LB10: INR | LC10: INR | LD10: INR | LE10: INR | LF10: INR | LG10: INR | LH10: INR | LI10: INR | LJ10: INR | LK10: INR | LL10: INR | LN10: INR | LO10: INR | LP10: INR | LQ10: INR | LR10: INR | LS10: INR | LT10: INR | LU10: INR | LV10: INR | LW10: INR | LX10: INR | LY10: INR | LZ10: INR | MB10: INR | MC10: =MB10 -> INR | MD10: =MC10 -> INR | ME10: =MD10 -> INR | MF10: =ME10 -> INR | MG10: =MF10 -> INR | MH10: =MG10 -> INR | MI10: =MH10 -> INR | MJ10: =MI10 -> INR | ... MN10: =MM10 -> INR
B11: Month (2025) | D11: 45688 | E11: 45716 | F11: 45747 | G11: 45777 | H11: 45808 | I11: 45838 | J11: 45869 | K11: 45900 | L11: 45930 | M11: 45961 | N11: 45991 | O11: 46022 | P11: Budget-2025 | R11: 45688 | S11: 45716 | T11: 45747 | U11: 45777 | V11: 45808 | W11: 45838 | X11: 45869 | Y11: 45900 | Z11: 45930 | AA11: 45961 | AB11: 45991 | AC11: 46022 | AD11: =+P11 -> Budget-2025 | AF11: 45688 | AG11: 45716 | AH11: 45747 | AI11: 45777 | AJ11: 45808 | AK11: 45838 | AL11: 45869 | AM11: 45900 | AN11: 45930 | AO11: 45961 | AP11: 45991 | AQ11: 46022 | AR11: =AD11 -> Budget-2025 | AT11: 45688 | AU11: 45716 | AV11: 45747 | AW11: 45777 | AX11: 45808 | AY11: 45838 | AZ11: 45869 | BA11: 45900 | BB11: 45930 | BC11: 45961 | BD11: 45991 | BE11: 46022 | BF11: =AR11 -> Budget-2025 | BH11: 45688 | BI11: 45716 | BJ11: 45747 | BK11: 45777 | BL11: 45808 | BM11: 45838 | BN11: 45869 | BO11: 45900 | BP11: 45930 | BQ11: 45961 | BR11: 45991 | BS11: 46022 | BT11: =+#REF! -> #REF! | BV11: 45688 | BW11: 45716 | BX11: 45747 | BY11: 45777 | BZ11: 45808 | CA11: 45838 | CB11: 45869 | CC11: 45900 | CD11: 45930 | CE11: 45961 | CF11: 45991 | CG11: 46022 | CH11: =+#REF! -> #REF! | CJ11: 45688 | CK11: 45716 | CL11: 45747 | CM11: 45777 | CN11: 45808 | CO11: 45838 | CP11: 45869 | CQ11: 45900 | CR11: 45930 | CS11: 45961 | CT11: 45991 | CU11: 46022 | CV11: =+#REF! -> #REF! | CX11: 45688 | CY11: 45716 | CZ11: 45747 | DA11: 45777 | DB11: 45808 | DC11: 45838 | DD11: 45869 | DE11: 45900 | DF11: 45930 | DG11: 45961 | DH11: 45991 | DI11: 46022 | DJ11: =+CV11 -> #REF! | DL11: 45688 | DM11: 45716 | DN11: 45747 | DO11: 45777 | DP11: 45808 | DQ11: 45838 | DR11: 45869 | DS11: 45900 | DT11: 45930 | DU11: 45961 | DV11: 45991 | DW11: 46022 | DX11: =+DJ11 -> #REF! | DZ11: 45688 | EA11: 45716 | EB11: 45747 | EC11: 45777 | ED11: 45808 | EE11: 45838 | EF11: 45869 | EG11: 45900 | EH11: 45930 | EI11: 45961 | EJ11: 45991 | EK11: 46022 | EL11: =+DX11 -> #REF! | EN11: 45688 | EO11: 45716 | EP11: 45747 | EQ11: 45777 | ER11: 45808 | ES11: 45838 | ET11: 45869 | EU11: 45900 | EV11: 45930 | EW11: 45961 | EX11: 45991 | EY11: 46022 | EZ11: =+EL11 -> #REF! | FB11: 45688 | FC11: 45716 | FD11: 45747 | FE11: 45777 | FF11: 45808 | FG11: 45838 | FH11: 45869 | FI11: 45900 | FJ11: 45930 | FK11: 45961 | FL11: 45991 | FM11: 46022 | FN11: =+EZ11 -> #REF! | FP11: 45688 | FQ11: 45716 | FR11: 45747 | FS11: 45777 | FT11: 45808 | FU11: 45838 | FV11: 45869 | FW11: 45900 | FX11: 45930 | FY11: 45961 | FZ11: 45991 | GA11: 46022 | GB11: =+FN11 -> #REF! | GD11: 45688 | GE11: 45716 | GF11: 45747 | GG11: 45777 | GH11: 45808 | GI11: 45838 | GJ11: 45869 | GK11: 45900 | GL11: 45930 | GM11: 45961 | GN11: 45991 | GO11: 46022 | GP11: =+#REF! -> #REF! | GR11: 45688 | GS11: 45716 | GT11: 45747 | GU11: 45777 | GV11: 45808 | GW11: 45838 | GX11: 45869 | GY11: 45900 | GZ11: 45930 | HA11: 45961 | HB11: 45991 | HC11: 46022 | HD11: =+LL11 -> Total | HF11: 45688 | HG11: 45716 | HH11: 45747 | HI11: 45777 | HJ11: 45808 | HK11: 45838 | HL11: 45869 | HM11: 45900 | HN11: 45930 | HO11: 45961 | HP11: 45991 | HQ11: 46022 | HR11: =+GP11 -> #REF! | HT11: 45688 | HU11: 45716 | HV11: 45747 | HW11: 45777 | HX11: 45808 | HY11: 45838 | HZ11: 45869 | IA11: 45900 | IB11: 45930 | IC11: 45961 | ID11: 45991 | IE11: 46022 | IF11: =+HR11 -> #REF! | IH11: 45688 | II11: 45716 | IJ11: 45747 | IK11: 45777 | IL11: 45808 | IM11: 45838 | IN11: 45869 | IO11: 45900 | IP11: 45930 | IQ11: 45961 | IR11: 45991 | IS11: 46022 | IT11: =+IF11 -> #REF! | IV11: 45688 | IW11: 45716 | IX11: 45747 | IY11: 45777 | IZ11: 45808 | JA11: 45838 | JB11: 45869 | JC11: 45900 | JD11: 45930 | JE11: 45961 | JF11: 45991 | JG11: 46022 | JH11: =+IT11 -> #REF! | JJ11: 45688 | JK11: 45716 | JL11: 45747 | JM11: 45777 | JN11: 45808 | JO11: 45838 | JP11: 45869 | JQ11: 45900 | JR11: 45930 | JS11: 45961 | JT11: 45991 | JU11: 46022 | JV11: =+JH11 -> #REF! | JX11: 45688 | JY11: 45716 | JZ11: 45747 | KA11: 45777 | KB11: 45808 | KC11: 45838 | KD11: 45869 | KE11: 45900 | KF11: 45930 | KG11: 45961 | KH11: 45991 | KI11: 46022 | KJ11: =+JV11 -> #REF! | KL11: 45688 | KM11: 45716 | KN11: 45747 | KO11: 45777 | KP11: 45808 | KQ11: 45838 | KR11: 45869 | KS11: 45900 | KT11: 45930 | KU11: 45961 | KV11: 45991 | KW11: 46022 | KX11: Total | KZ11: 45688 | LA11: 45716 | LB11: 45747 | LC11: 45777 | LD11: 45808 | LE11: 45838 | LF11: 45869 | LG11: 45900 | LH11: 45930 | LI11: 45961 | LJ11: 45991 | LK11: 46022 | LL11: =+KX11 -> Total | LN11: 45688 | LO11: 45716 | LP11: 45747 | LQ11: 45777 | LR11: 45808 | LS11: 45838 | LT11: 45869 | LU11: 45900 | LV11: 45930 | LW11: 45961 | LX11: 45991 | LY11: 46022 | LZ11: =+HD11 -> Total | MB11: Total | MC11: =MB11 -> Total | MD11: =MC11 -> Total | ME11: =MD11 -> Total | MF11: =ME11 -> Total | MG11: =MF11 -> Total | MH11: =MG11 -> Total | MI11: =MH11 -> Total | MJ11: =MI11 -> Total | ... MN11: =MM11 -> Total
B12: Unique BU-Division Name | D12: Accounts-Fleet Accounts | E12: Accounts-Fleet Accounts | F12: Accounts-Fleet Accounts | G12: Accounts-Fleet Accounts | H12: Accounts-Fleet Accounts | I12: Accounts-Fleet Accounts | J12: Accounts-Fleet Accounts | K12: Accounts-Fleet Accounts | L12: Accounts-Fleet Accounts | M12: Accounts-Fleet Accounts | N12: Accounts-Fleet Accounts | O12: Accounts-Fleet Accounts | P12: Accounts-Fleet Accounts | R12: Admin-Administration | S12: Admin-Administration | T12: Admin-Administration | U12: Admin-Administration | V12: Admin-Administration | W12: Admin-Administration | X12: Admin-Administration | Y12: Admin-Administration | Z12: Admin-Administration | AA12: Admin-Administration | AB12: Admin-Administration | AC12: Admin-Administration | AD12: Admin-Administration | AF12: Agency Services-Agency Hub | AG12: Agency Services-Agency Hub | AH12: Agency Services-Agency Hub | AI12: Agency Services-Agency Hub | AJ12: Agency Services-Agency Hub | AK12: Agency Services-Agency Hub | AL12: Agency Services-Agency Hub | AM12: Agency Services-Agency Hub | AN12: Agency Services-Agency Hub | AO12: Agency Services-Agency Hub | AP12: Agency Services-Agency Hub | AQ12: Agency Services-Agency Hub | AR12: Agency Services-Agency Hub | AT12: Commercial-Commercial | AU12: Commercial-Commercial | AV12: Commercial-Commercial | AW12: Commercial-Commercial | AX12: Commercial-Commercial | AY12: Commercial-Commercial | AZ12: Commercial-Commercial | BA12: Commercial-Commercial | BB12: Commercial-Commercial | BC12: Commercial-Commercial | BD12: Commercial-Commercial | BE12: Commercial-Commercial | BF12: Commercial-Commercial | BH12: Consultancy Services-Fleet Performance | BI12: Consultancy Services-Fleet Performance | BJ12: Consultancy Services-Fleet Performance | BK12: Consultancy Services-Fleet Performance | BL12: Consultancy Services-Fleet Performance | BM12: Consultancy Services-Fleet Performance | BN12: Consultancy Services-Fleet Performance | BO12: Consultancy Services-Fleet Performance | BP12: Consultancy Services-Fleet Performance | BQ12: Consultancy Services-Fleet Performance | BR12: Consultancy Services-Fleet Performance | BS12: Consultancy Services-Fleet Performance | BT12: Consultancy Services-Fleet Performance | BV12: Crew Management-Group Marine HR | BW12: Crew Management-Group Marine HR | BX12: Crew Management-Group Marine HR | BY12: Crew Management-Group Marine HR | BZ12: Crew Management-Group Marine HR | CA12: Crew Management-Group Marine HR | CB12: Crew Management-Group Marine HR | CC12: Crew Management-Group Marine HR | CD12: Crew Management-Group Marine HR | CE12: Crew Management-Group Marine HR | CF12: Crew Management-Group Marine HR | CG12: Crew Management-Group Marine HR | CH12: Crew Management-Group Marine HR | CJ12: Cruise Management-Miami Ship Management | CK12: Cruise Management-Miami Ship Management | CL12: Cruise Management-Miami Ship Management | CM12: Cruise Management-Miami Ship Management | CN12: Cruise Management-Miami Ship Management | CO12: Cruise Management-Miami Ship Management | CP12: Cruise Management-Miami Ship Management | CQ12: Cruise Management-Miami Ship Management | CR12: Cruise Management-Miami Ship Management | CS12: Cruise Management-Miami Ship Management | CT12: Cruise Management-Miami Ship Management | CU12: Cruise Management-Miami Ship Management | CV12: Cruise Management-Miami Ship Management | CX12: IT-Group IT | CY12: IT-Group IT | CZ12: IT-Group IT | DA12: IT-Group IT | DB12: IT-Group IT | DC12: IT-Group IT | DD12: IT-Group IT | DE12: IT-Group IT | DF12: IT-Group IT | DG12: IT-Group IT | DH12: IT-Group IT | DI12: IT-Group IT | DJ12: IT-Group IT | DL12: Procurement-Galleymasters | DM12: Procurement-Galleymasters | DN12: Procurement-Galleymasters | DO12: Procurement-Galleymasters | DP12: Procurement-Galleymasters | DQ12: Procurement-Galleymasters | DR12: Procurement-Galleymasters | DS12: Procurement-Galleymasters | DT12: Procurement-Galleymasters | DU12: Procurement-Galleymasters | DV12: Procurement-Galleymasters | DW12: Procurement-Galleymasters | DX12: Procurement-Galleymasters | DZ12: Procurement-Sourcing | EA12: Procurement-Sourcing | EB12: Procurement-Sourcing | EC12: Procurement-Sourcing | ED12: Procurement-Sourcing | EE12: Procurement-Sourcing | EF12: Procurement-Sourcing | EG12: Procurement-Sourcing | EH12: Procurement-Sourcing | EI12: Procurement-Sourcing | EJ12: Procurement-Sourcing | EK12: Procurement-Sourcing | EL12: Procurement-Sourcing | EN12: Ship Management-Antwerp Dry | EO12: Ship Management-Antwerp Dry | EP12: Ship Management-Antwerp Dry | EQ12: Ship Management-Antwerp Dry | ER12: Ship Management-Antwerp Dry | ES12: Ship Management-Antwerp Dry | ET12: Ship Management-Antwerp Dry | EU12: Ship Management-Antwerp Dry | EV12: Ship Management-Antwerp Dry | EW12: Ship Management-Antwerp Dry | EX12: Ship Management-Antwerp Dry | EY12: Ship Management-Antwerp Dry | EZ12: Ship Management-Antwerp Dry | FB12: Ship Management-Goes Dry | FC12: Ship Management-Goes Dry | FD12: Ship Management-Goes Dry | FE12: Ship Management-Goes Dry | FF12: Ship Management-Goes Dry | FG12: Ship Management-Goes Dry | FH12: Ship Management-Goes Dry | FI12: Ship Management-Goes Dry | FJ12: Ship Management-Goes Dry | FK12: Ship Management-Goes Dry | FL12: Ship Management-Goes Dry | FM12: Ship Management-Goes Dry | FN12: Ship Management-Goes Dry | FP12: Ship Management-Group Operations | FQ12: Ship Management-Group Operations | FR12: Ship Management-Group Operations | FS12: Ship Management-Group Operations | FT12: Ship Management-Group Operations | FU12: Ship Management-Group Operations | FV12: Ship Management-Group Operations | FW12: Ship Management-Group Operations | FX12: Ship Management-Group Operations | FY12: Ship Management-Group Operations | FZ12: Ship Management-Group Operations | GA12: Ship Management-Group Operations | GB12: Ship Management-Group Operations | GD12: Ship Management-Group Shared Service Center | GE12: Ship Management-Group Shared Service Center | GF12: Ship Management-Group Shared Service Center | GG12: Ship Management-Group Shared Service Center | GH12: Ship Management-Group Shared Service Center | GI12: Ship Management-Group Shared Service Center | GJ12: Ship Management-Group Shared Service Center | GK12: Ship Management-Group Shared Service Center | GL12: Ship Management-Group Shared Service Center | GM12: Ship Management-Group Shared Service Center | GN12: Ship Management-Group Shared Service Center | GO12: Ship Management-Group Shared Service Center | GP12: Ship Management-Group Shared Service Center | GR12: Vacant Seats | GS12: Vacant Seats | GT12: Vacant Seats | GU12: Vacant Seats | GV12: Vacant Seats | GW12: Vacant Seats | GX12: Vacant Seats | GY12: Vacant Seats | GZ12: Vacant Seats | HA12: Vacant Seats | HB12: Vacant Seats | HC12: Vacant Seats | HD12: Vacant Seats | HF12: Ship Management-Hamburg Dry | HG12: Ship Management-Hamburg Dry | HH12: Ship Management-Hamburg Dry | HI12: Ship Management-Hamburg Dry | HJ12: Ship Management-Hamburg Dry | HK12: Ship Management-Hamburg Dry | HL12: Ship Management-Hamburg Dry | HM12: Ship Management-Hamburg Dry | HN12: Ship Management-Hamburg Dry | HO12: Ship Management-Hamburg Dry | HP12: Ship Management-Hamburg Dry | HQ12: Ship Management-Hamburg Dry | HR12: Ship Management-Hamburg Dry | HT12: Ship Management-Hong Kong Dry 1 | HU12: Ship Management-Hong Kong Dry 1 | HV12: Ship Management-Hong Kong Dry 1 | HW12: Ship Management-Hong Kong Dry 1 | HX12: Ship Management-Hong Kong Dry 1 | HY12: Ship Management-Hong Kong Dry 1 | HZ12: Ship Management-Hong Kong Dry 1 | IA12: Ship Management-Hong Kong Dry 1 | IB12: Ship Management-Hong Kong Dry 1 | IC12: Ship Management-Hong Kong Dry 1 | ID12: Ship Management-Hong Kong Dry 1 | IE12: Ship Management-Hong Kong Dry 1 | IF12: Ship Management-Hong Kong Dry 1 | IH12: Ship Management-JV Ardmore | II12: Ship Management-JV Ardmore | IJ12: Ship Management-JV Ardmore | IK12: Ship Management-JV Ardmore | IL12: Ship Management-JV Ardmore | IM12: Ship Management-JV Ardmore | IN12: Ship Management-JV Ardmore | IO12: Ship Management-JV Ardmore | IP12: Ship Management-JV Ardmore | IQ12: Ship Management-JV Ardmore | IR12: Ship Management-JV Ardmore | IS12: Ship Management-JV Ardmore | IT12: Ship Management-JV Ardmore | IV12: Ship Management-Singapore Dry | IW12: Ship Management-Singapore Dry | IX12: Ship Management-Singapore Dry | IY12: Ship Management-Singapore Dry | IZ12: Ship Management-Singapore Dry | JA12: Ship Management-Singapore Dry | JB12: Ship Management-Singapore Dry | JC12: Ship Management-Singapore Dry | JD12: Ship Management-Singapore Dry | JE12: Ship Management-Singapore Dry | JF12: Ship Management-Singapore Dry | JG12: Ship Management-Singapore Dry | JH12: Ship Management-Singapore Dry | JJ12: Ship Management-Singapore Tanker 1 | JK12: Ship Management-Singapore Tanker 1 | JL12: Ship Management-Singapore Tanker 1 | JM12: Ship Management-Singapore Tanker 1 | JN12: Ship Management-Singapore Tanker 1 | JO12: Ship Management-Singapore Tanker 1 | JP12: Ship Management-Singapore Tanker 1 | JQ12: Ship Management-Singapore Tanker 1 | JR12: Ship Management-Singapore Tanker 1 | JS12: Ship Management-Singapore Tanker 1 | JT12: Ship Management-Singapore Tanker 1 | JU12: Ship Management-Singapore Tanker 1 | JV12: Ship Management-Singapore Tanker 1 | JX12: Ship Management-Singapore Tanker 2 | JY12: Ship Management-Singapore Tanker 2 | JZ12: Ship Management-Singapore Tanker 2 | KA12: Ship Management-Singapore Tanker 2 | KB12: Ship Management-Singapore Tanker 2 | KC12: Ship Management-Singapore Tanker 2 | KD12: Ship Management-Singapore Tanker 2 | KE12: Ship Management-Singapore Tanker 2 | KF12: Ship Management-Singapore Tanker 2 | KG12: Ship Management-Singapore Tanker 2 | KH12: Ship Management-Singapore Tanker 2 | KI12: Ship Management-Singapore Tanker 2 | KJ12: Ship Management-Singapore Tanker 2 | KL12: Accounts-Accounts Payables | KM12: Accounts-Accounts Payables | KN12: Accounts-Accounts Payables | KO12: Accounts-Accounts Payables | KP12: Accounts-Accounts Payables | KQ12: Accounts-Accounts Payables | KR12: Accounts-Accounts Payables | KS12: Accounts-Accounts Payables | KT12: Accounts-Accounts Payables | KU12: Accounts-Accounts Payables | KV12: Accounts-Accounts Payables | KW12: Accounts-Accounts Payables | KX12: Accounts-Accounts Payables | KZ12: Accounts-CMI Accounts Payables | LA12: Accounts-CMI Accounts Payables | LB12: Accounts-CMI Accounts Payables | LC12: Accounts-CMI Accounts Payables | LD12: Accounts-CMI Accounts Payables | LE12: Accounts-CMI Accounts Payables | LF12: Accounts-CMI Accounts Payables | LG12: Accounts-CMI Accounts Payables | LH12: Accounts-CMI Accounts Payables | LI12: Accounts-CMI Accounts Payables | LJ12: Accounts-CMI Accounts Payables | LK12: Accounts-CMI Accounts Payables | LL12: Accounts-CMI Accounts Payables | MB12: 30 Divisions | MC12: =MB12 -> 30 Divisions | MD12: =MC12 -> 30 Divisions | ME12: =MD12 -> 30 Divisions | MF12: =ME12 -> 30 Divisions | MG12: =MF12 -> 30 Divisions | MH12: =MG12 -> 30 Divisions | MI12: =MH12 -> 30 Divisions | MJ12: =MI12 -> 30 Divisions | ... MN12: =MM12 -> 30 Divisions
B13: INCOME
B14: Ship Management - Other Income | D14: 0 | E14: 0 | F14: 0 | G14: 0 | H14: 0 | I14: 0 | J14: 0 | K14: 0 | L14: 0 | M14: 0 | N14: 0 | O14: 0 | P14: =+SUBTOTAL(9,D14:O14) -> 0 | R14: 0 | S14: 0 | T14: 0 | U14: 0 | V14: 0 | W14: 0 | X14: 0 | Y14: 0 | Z14: 0 | AA14: 0 | AB14: 0 | AC14: 0 | AD14: =+SUBTOTAL(9,R14:AC14) -> 0 | AF14: 0 | AG14: 0 | AH14: 0 | AI14: 0 | AJ14: 0 | AK14: 0 | AL14: 0 | AM14: 0 | AN14: 0 | AO14: 0 | AP14: 0 | AQ14: 0 | AR14: =+SUBTOTAL(9,AF14:AQ14) -> 0 | AT14: 0 | AU14: 0 | AV14: 0 | AW14: 0 | AX14: 0 | AY14: 0 | AZ14: 0 | BA14: 0 | BB14: 0 | BC14: 0 | BD14: 0 | BE14: 0 | BF14: =+SUBTOTAL(9,AT14:BE14) -> 0 | BH14: 0 | BI14: 0 | BJ14: 0 | BK14: 0 | BL14: 0 | BM14: 0 | BN14: 0 | BO14: 0 | BP14: 0 | BQ14: 0 | BR14: 0 | BS14: 0 | BT14: =+SUBTOTAL(9,BH14:BS14) -> 0 | BV14: 0 | BW14: 0 | BX14: 0 | BY14: 0 | BZ14: 0 | CA14: 0 | CB14: 0 | CC14: 0 | CD14: 0 | CE14: 0 | CF14: 0 | CG14: 0 | CH14: =+SUBTOTAL(9,BV14:CG14) -> 0 | CJ14: 0 | CK14: 0 | CL14: 0 | CM14: 0 | CN14: 0 | CO14: 0 | CP14: 0 | CQ14: 0 | CR14: 0 | CS14: 0 | CT14: 0 | CU14: 0 | CV14: =+SUBTOTAL(9,CJ14:CU14) -> 0 | CX14: 0 | CY14: 0 | CZ14: 0 | DA14: 0 | DB14: 0 | DC14: 0 | DD14: 0 | DE14: 0 | DF14: 0 | DG14: 0 | DH14: 0 | DI14: 0 | DJ14: =+SUBTOTAL(9,CX14:DI14) -> 0 | DL14: 0 | DM14: 0 | DN14: 0 | DO14: 0 | DP14: 0 | DQ14: 0 | DR14: 0 | DS14: 0 | DT14: 0 | DU14: 0 | DV14: 0 | DW14: 0 | DX14: =+SUBTOTAL(9,DL14:DW14) -> 0 | DZ14: 0 | EA14: 0 | EB14: 0 | EC14: 0 | ED14: 0 | EE14: 0 | EF14: 0 | EG14: 0 | EH14: 0 | EI14: 0 | EJ14: 0 | EK14: 0 | EL14: =+SUBTOTAL(9,DZ14:EK14) -> 0 | EN14: 0 | EO14: 0 | EP14: 0 | EQ14: 0 | ER14: 0 | ES14: 0 | ET14: 0 | EU14: 0 | EV14: 0 | EW14: 0 | EX14: 0 | EY14: 0 | EZ14: =+SUBTOTAL(9,EN14:EY14) -> 0 | FB14: 0 | FC14: 0 | FD14: 0 | FE14: 0 | FF14: 0 | FG14: 0 | FH14: 0 | FI14: 0 | FJ14: 0 | FK14: 0 | FL14: 0 | FM14: 0 | FN14: =+SUBTOTAL(9,FB14:FM14) -> 0 | FP14: 0 | FQ14: 0 | FR14: 0 | FS14: 0 | FT14: 0 | FU14: 0 | FV14: 0 | FW14: 0 | FX14: 0 | FY14: 0 | FZ14: 0 | GA14: 0 | GB14: =+SUBTOTAL(9,FP14:GA14) -> 0 | GD14: 0 | GE14: 0 | GF14: 0 | GG14: 0 | GH14: 0 | GI14: 0 | GJ14: 0 | GK14: 0 | GL14: 0 | GM14: 0 | GN14: 0 | GO14: 0 | GP14: =+SUBTOTAL(9,GD14:GO14) -> 0 | GR14: 0 | GS14: 0 | GT14: 0 | GU14: 0 | GV14: 0 | GW14: 0 | GX14: 0 | GY14: 0 | GZ14: 0 | HA14: 0 | HB14: 0 | HC14: 0 | HD14: =+SUBTOTAL(9,GR14:HC14) -> 0 | HF14: 0 | HG14: 0 | HH14: 0 | HI14: 0 | HJ14: 0 | HK14: 0 | HL14: 0 | HM14: 0 | HN14: 0 | HO14: 0 | HP14: 0 | HQ14: 0 | HR14: =+SUBTOTAL(9,HF14:HQ14) -> 0 | HT14: 0 | HU14: 0 | HV14: 0 | HW14: 0 | HX14: 0 | HY14: 0 | HZ14: 0 | IA14: 0 | IB14: 0 | IC14: 0 | ID14: 0 | IE14: 0 | IF14: =+SUBTOTAL(9,HT14:IE14) -> 0 | IH14: 0 | II14: 0 | IJ14: 0 | IK14: 0 | IL14: 0 | IM14: 0 | IN14: 0 | IO14: 0 | IP14: 0 | IQ14: 0 | IR14: 0 | IS14: 0 | IT14: =+SUBTOTAL(9,IH14:IS14) -> 0 | IV14: 0 | IW14: 0 | IX14: 0 | IY14: 0 | IZ14: 0 | JA14: 0 | JB14: 0 | JC14: 0 | JD14: 0 | JE14: 0 | JF14: 0 | JG14: 0 | JH14: =+SUBTOTAL(9,IV14:JG14) -> 0 | JJ14: 0 | JK14: 0 | JL14: 0 | JM14: 0 | JN14: 0 | JO14: 0 | JP14: 0 | JQ14: 0 | JR14: 0 | JS14: 0 | JT14: 0 | JU14: 0 | JV14: =+SUBTOTAL(9,JJ14:JU14) -> 0 | JX14: 0 | JY14: 0 | JZ14: 0 | KA14: 0 | KB14: 0 | KC14: 0 | KD14: 0 | KE14: 0 | KF14: 0 | KG14: 0 | KH14: 0 | KI14: 0 | KJ14: =+SUBTOTAL(9,JX14:KI14) -> 0 | KL14: 0 | KM14: 0 | KN14: 0 | KO14: 0 | KP14: 0 | KQ14: 0 | KR14: 0 | KS14: 0 | KT14: 0 | KU14: 0 | KV14: 0 | KW14: 0 | KX14: =+SUBTOTAL(9,KL14:KW14) -> 0 | KZ14: 0 | LA14: 0 | LB14: 0 | LC14: 0 | LD14: 0 | LE14: 0 | LF14: 0 | LG14: 0 | LH14: 0 | LI14: 0 | LJ14: 0 | LK14: 0 | LL14: =+SUBTOTAL(9,KZ14:LK14) -> 0 | LN14: 0 | LO14: 0 | LP14: 0 | LQ14: 0 | LR14: 0 | LS14: 0 | LT14: 0 | LU14: 0 | LV14: 0 | LW14: 0 | LX14: 0 | LY14: 0 | LZ14: =+SUBTOTAL(9,LN14:LY14) -> 0 | MB14: =SUMIF($D$11:$LY$11,MB$8,$D14:$LY14) -> 0 | MC14: =SUMIF($D$11:$LY$11,MC$8,$D14:$LY14) -> 0 | MD14: =SUMIF($D$11:$LY$11,MD$8,$D14:$LY14) -> 0 | ME14: =SUMIF($D$11:$LY$11,ME$8,$D14:$LY14) -> 0 | MF14: =SUMIF($D$11:$LY$11,MF$8,$D14:$LY14) -> 0 | MG14: =SUMIF($D$11:$LY$11,MG$8,$D14:$LY14) -> 0 | MH14: =SUMIF($D$11:$LY$11,MH$8,$D14:$LY14) -> 0 | MI14: =SUMIF($D$11:$LY$11,MI$8,$D14:$LY14) -> 0 | ... MM14: =SUMIF($D$11:$LY$11,MM$8,$D14:$LY14) -> 0 | MN14: =SUM(MB14:MM14) -> 0
B15: Intercompany Sales | D15: 0 | E15: 0 | F15: 0 | G15: 0 | H15: 0 | I15: 0 | J15: 0 | K15: 0 | L15: 0 | M15: 0 | N15: 0 | O15: 0 | P15: =+SUBTOTAL(9,D15:O15) -> 0 | R15: 0 | S15: 0 | T15: 0 | U15: 0 | V15: 0 | W15: 0 | X15: 0 | Y15: 0 | Z15: 0 | AA15: 0 | AB15: 0 | AC15: 0 | AD15: =+SUBTOTAL(9,R15:AC15) -> 0 | AF15: 0 | AG15: 0 | AH15: 0 | AI15: 0 | AJ15: 0 | AK15: 0 | AL15: 0 | AM15: 0 | AN15: 0 | AO15: 0 | AP15: 0 | AQ15: 0 | AR15: =+SUBTOTAL(9,AF15:AQ15) -> 0 | AT15: 0 | AU15: 0 | AV15: 0 | AW15: 0 | AX15: 0 | AY15: 0 | AZ15: 0 | BA15: 0 | BB15: 0 | BC15: 0 | BD15: 0 | BE15: 0 | BF15: =+SUBTOTAL(9,AT15:BE15) -> 0 | BH15: 0 | BI15: 0 | BJ15: 0 | BK15: 0 | BL15: 0 | BM15: 0 | BN15: 0 | BO15: 0 | BP15: 0 | BQ15: 0 | BR15: 0 | BS15: 0 | BT15: =+SUBTOTAL(9,BH15:BS15) -> 0 | BV15: 0 | BW15: 0 | BX15: 0 | BY15: 0 | BZ15: 0 | CA15: 0 | CB15: 0 | CC15: 0 | CD15: 0 | CE15: 0 | CF15: 0 | CG15: 0 | CH15: =+SUBTOTAL(9,BV15:CG15) -> 0 | CJ15: 0 | CK15: 0 | CL15: 0 | CM15: 0 | CN15: 0 | CO15: 0 | CP15: 0 | CQ15: 0 | CR15: 0 | CS15: 0 | CT15: 0 | CU15: 0 | CV15: =+SUBTOTAL(9,CJ15:CU15) -> 0 | CX15: 0 | CY15: 0 | CZ15: 0 | DA15: 0 | DB15: 0 | DC15: 0 | DD15: 0 | DE15: 0 | DF15: 0 | DG15: 0 | DH15: 0 | DI15: 0 | DJ15: =+SUBTOTAL(9,CX15:DI15) -> 0 | DL15: 0 | DM15: 0 | DN15: 0 | DO15: 0 | DP15: 0 | DQ15: 0 | DR15: 0 | DS15: 0 | DT15: 0 | DU15: 0 | DV15: 0 | DW15: 0 | DX15: =+SUBTOTAL(9,DL15:DW15) -> 0 | DZ15: 0 | EA15: 0 | EB15: 0 | EC15: 0 | ED15: 0 | EE15: 0 | EF15: 0 | EG15: 0 | EH15: 0 | EI15: 0 | EJ15: 0 | EK15: 0 | EL15: =+SUBTOTAL(9,DZ15:EK15) -> 0 | EN15: 0 | EO15: 0 | EP15: 0 | EQ15: 0 | ER15: 0 | ES15: 0 | ET15: 0 | EU15: 0 | EV15: 0 | EW15: 0 | EX15: 0 | EY15: 0 | EZ15: =+SUBTOTAL(9,EN15:EY15) -> 0 | FB15: 0 | FC15: 0 | FD15: 0 | FE15: 0 | FF15: 0 | FG15: 0 | FH15: 0 | FI15: 0 | FJ15: 0 | FK15: 0 | FL15: 0 | FM15: 0 | FN15: =+SUBTOTAL(9,FB15:FM15) -> 0 | FP15: 0 | FQ15: 0 | FR15: 0 | FS15: 0 | FT15: 0 | FU15: 0 | FV15: 0 | FW15: 0 | FX15: 0 | FY15: 0 | FZ15: 0 | GA15: 0 | GB15: =+SUBTOTAL(9,FP15:GA15) -> 0 | GD15: 0 | GE15: 0 | GF15: 0 | GG15: 0 | GH15: 0 | GI15: 0 | GJ15: 0 | GK15: 0 | GL15: 0 | GM15: 0 | GN15: 0 | GO15: 0 | GP15: =+SUBTOTAL(9,GD15:GO15) -> 0 | GR15: 0 | GS15: 0 | GT15: 0 | GU15: 0 | GV15: 0 | GW15: 0 | GX15: 0 | GY15: 0 | GZ15: 0 | HA15: 0 | HB15: 0 | HC15: 0 | HD15: =+SUBTOTAL(9,GR15:HC15) -> 0 | HF15: 0 | HG15: 0 | HH15: 0 | HI15: 0 | HJ15: 0 | HK15: 0 | HL15: 0 | HM15: 0 | HN15: 0 | HO15: 0 | HP15: 0 | HQ15: 0 | HR15: =+SUBTOTAL(9,HF15:HQ15) -> 0 | HT15: 0 | HU15: 0 | HV15: 0 | HW15: 0 | HX15: 0 | HY15: 0 | HZ15: 0 | IA15: 0 | IB15: 0 | IC15: 0 | ID15: 0 | IE15: 0 | IF15: =+SUBTOTAL(9,HT15:IE15) -> 0 | IH15: 0 | II15: 0 | IJ15: 0 | IK15: 0 | IL15: 0 | IM15: 0 | IN15: 0 | IO15: 0 | IP15: 0 | IQ15: 0 | IR15: 0 | IS15: 0 | IT15: =+SUBTOTAL(9,IH15:IS15) -> 0 | IV15: 0 | IW15: 0 | IX15: 0 | IY15: 0 | IZ15: 0 | JA15: 0 | JB15: 0 | JC15: 0 | JD15: 0 | JE15: 0 | JF15: 0 | JG15: 0 | JH15: =+SUBTOTAL(9,IV15:JG15) -> 0 | JJ15: 0 | JK15: 0 | JL15: 0 | JM15: 0 | JN15: 0 | JO15: 0 | JP15: 0 | JQ15: 0 | JR15: 0 | JS15: 0 | JT15: 0 | JU15: 0 | JV15: =+SUBTOTAL(9,JJ15:JU15) -> 0 | JX15: 0 | JY15: 0 | JZ15: 0 | KA15: 0 | KB15: 0 | KC15: 0 | KD15: 0 | KE15: 0 | KF15: 0 | KG15: 0 | KH15: 0 | KI15: 0 | KJ15: =+SUBTOTAL(9,JX15:KI15) -> 0 | KL15: 0 | KM15: 0 | KN15: 0 | KO15: 0 | KP15: 0 | KQ15: 0 | KR15: 0 | KS15: 0 | KT15: 0 | KU15: 0 | KV15: 0 | KW15: 0 | KX15: =+SUBTOTAL(9,KL15:KW15) -> 0 | KZ15: 0 | LA15: 0 | LB15: 0 | LC15: 0 | LD15: 0 | LE15: 0 | LF15: 0 | LG15: 0 | LH15: 0 | LI15: 0 | LJ15: 0 | LK15: 0 | LL15: =+SUBTOTAL(9,KZ15:LK15) -> 0 | LN15: 0 | LO15: 0 | LP15: 0 | LQ15: 0 | LR15: 0 | LS15: 0 | LT15: 0 | LU15: 0 | LV15: 0 | LW15: 0 | LX15: 0 | LY15: 0 | LZ15: =+SUBTOTAL(9,LN15:LY15) -> 0 | MB15: =SUMIF($D$11:$LY$11,MB$8,$D15:$LY15) -> 0 | MC15: =SUMIF($D$11:$LY$11,MC$8,$D15:$LY15) -> 0 | MD15: =SUMIF($D$11:$LY$11,MD$8,$D15:$LY15) -> 0 | ME15: =SUMIF($D$11:$LY$11,ME$8,$D15:$LY15) -> 0 | MF15: =SUMIF($D$11:$LY$11,MF$8,$D15:$LY15) -> 0 | MG15: =SUMIF($D$11:$LY$11,MG$8,$D15:$LY15) -> 0 | MH15: =SUMIF($D$11:$LY$11,MH$8,$D15:$LY15) -> 0 | MI15: =SUMIF($D$11:$LY$11,MI$8,$D15:$LY15) -> 0 | ... MM15: =SUMIF($D$11:$LY$11,MM$8,$D15:$LY15) -> 0 | MN15: =SUM(MB15:MM15) -> 0
B17: TOTAL INCOME | D17: =SUM(D14:D16) -> 0 | E17: =SUM(E14:E16) -> 0 | F17: =SUM(F14:F16) -> 0 | G17: =SUM(G14:G16) -> 0 | H17: =SUM(H14:H16) -> 0 | I17: =SUM(I14:I16) -> 0 | J17: =SUM(J14:J16) -> 0 | K17: =SUM(K14:K16) -> 0 | ... O17: =SUM(O14:O16) -> 0 | P17: =+SUBTOTAL(9,D17:O17) -> 0 | R17: =SUM(R14:R16) -> 0 | S17: =SUM(S14:S16) -> 0 | T17: =SUM(T14:T16) -> 0 | U17: =SUM(U14:U16) -> 0 | V17: =SUM(V14:V16) -> 0 | W17: =SUM(W14:W16) -> 0 | X17: =SUM(X14:X16) -> 0 | Y17: =SUM(Y14:Y16) -> 0 | ... AC17: =SUM(AC14:AC16) -> 0 | AD17: =+SUBTOTAL(9,R17:AC17) -> 0 | AF17: =SUM(AF14:AF16) -> 0 | AG17: =SUM(AG14:AG16) -> 0 | AH17: =SUM(AH14:AH16) -> 0 | AI17: =SUM(AI14:AI16) -> 0 | AJ17: =SUM(AJ14:AJ16) -> 0 | AK17: =SUM(AK14:AK16) -> 0 | AL17: =SUM(AL14:AL16) -> 0 | AM17: =SUM(AM14:AM16) -> 0 | ... AQ17: =SUM(AQ14:AQ16) -> 0 | AR17: =+SUBTOTAL(9,AF17:AQ17) -> 0 | AT17: =SUM(AT14:AT16) -> 0 | AU17: =SUM(AU14:AU16) -> 0 | AV17: =SUM(AV14:AV16) -> 0 | AW17: =SUM(AW14:AW16) -> 0 | AX17: =SUM(AX14:AX16) -> 0 | AY17: =SUM(AY14:AY16) -> 0 | AZ17: =SUM(AZ14:AZ16) -> 0 | BA17: =SUM(BA14:BA16) -> 0 | ... BE17: =SUM(BE14:BE16) -> 0 | BF17: =+SUBTOTAL(9,AT17:BE17) -> 0 | BH17: =SUM(BH14:BH16) -> 0 | BI17: =SUM(BI14:BI16) -> 0 | BJ17: =SUM(BJ14:BJ16) -> 0 | BK17: =SUM(BK14:BK16) -> 0 | BL17: =SUM(BL14:BL16) -> 0 | BM17: =SUM(BM14:BM16) -> 0 | BN17: =SUM(BN14:BN16) -> 0 | BO17: =SUM(BO14:BO16) -> 0 | ... BS17: =SUM(BS14:BS16) -> 0 | BT17: =+SUBTOTAL(9,BH17:BS17) -> 0 | BV17: =SUM(BV14:BV16) -> 0 | BW17: =SUM(BW14:BW16) -> 0 | BX17: =SUM(BX14:BX16) -> 0 | BY17: =SUM(BY14:BY16) -> 0 | BZ17: =SUM(BZ14:BZ16) -> 0 | CA17: =SUM(CA14:CA16) -> 0 | CB17: =SUM(CB14:CB16) -> 0 | CC17: =SUM(CC14:CC16) -> 0 | ... CG17: =SUM(CG14:CG16) -> 0 | CH17: =+SUBTOTAL(9,BV17:CG17) -> 0 | CJ17: =SUM(CJ14:CJ16) -> 0 | CK17: =SUM(CK14:CK16) -> 0 | CL17: =SUM(CL14:CL16) -> 0 | CM17: =SUM(CM14:CM16) -> 0 | CN17: =SUM(CN14:CN16) -> 0 | CO17: =SUM(CO14:CO16) -> 0 | CP17: =SUM(CP14:CP16) -> 0 | CQ17: =SUM(CQ14:CQ16) -> 0 | ... CU17: =SUM(CU14:CU16) -> 0 | CV17: =+SUBTOTAL(9,CJ17:CU17) -> 0 | CX17: =SUM(CX14:CX16) -> 0 | CY17: =SUM(CY14:CY16) -> 0 | CZ17: =SUM(CZ14:CZ16) -> 0 | DA17: =SUM(DA14:DA16) -> 0 | DB17: =SUM(DB14:DB16) -> 0 | DC17: =SUM(DC14:DC16) -> 0 | DD17: =SUM(DD14:DD16) -> 0 | DE17: =SUM(DE14:DE16) -> 0 | ... DI17: =SUM(DI14:DI16) -> 0 | DJ17: =+SUBTOTAL(9,CX17:DI17) -> 0 | DL17: =SUM(DL14:DL16) -> 0 | DM17: =SUM(DM14:DM16) -> 0 | DN17: =SUM(DN14:DN16) -> 0 | DO17: =SUM(DO14:DO16) -> 0 | DP17: =SUM(DP14:DP16) -> 0 | DQ17: =SUM(DQ14:DQ16) -> 0 | DR17: =SUM(DR14:DR16) -> 0 | DS17: =SUM(DS14:DS16) -> 0 | ... DW17: =SUM(DW14:DW16) -> 0 | DX17: =+SUBTOTAL(9,DL17:DW17) -> 0 | DZ17: =SUM(DZ14:DZ16) -> 0 | EA17: =SUM(EA14:EA16) -> 0 | EB17: =SUM(EB14:EB16) -> 0 | EC17: =SUM(EC14:EC16) -> 0 | ED17: =SUM(ED14:ED16) -> 0 | EE17: =SUM(EE14:EE16) -> 0 | EF17: =SUM(EF14:EF16) -> 0 | EG17: =SUM(EG14:EG16) -> 0 | ... EK17: =SUM(EK14:EK16) -> 0 | EL17: =+SUBTOTAL(9,DZ17:EK17) -> 0 | EN17: =SUM(EN14:EN16) -> 0 | EO17: =SUM(EO14:EO16) -> 0 | EP17: =SUM(EP14:EP16) -> 0 | EQ17: =SUM(EQ14:EQ16) -> 0 | ER17: =SUM(ER14:ER16) -> 0 | ES17: =SUM(ES14:ES16) -> 0 | ET17: =SUM(ET14:ET16) -> 0 | EU17: =SUM(EU14:EU16) -> 0 | ... EY17: =SUM(EY14:EY16) -> 0 | EZ17: =+SUBTOTAL(9,EN17:EY17) -> 0 | FB17: =SUM(FB14:FB16) -> 0 | FC17: =SUM(FC14:FC16) -> 0 | FD17: =SUM(FD14:FD16) -> 0 | FE17: =SUM(FE14:FE16) -> 0 | FF17: =SUM(FF14:FF16) -> 0 | FG17: =SUM(FG14:FG16) -> 0 | FH17: =SUM(FH14:FH16) -> 0 | FI17: =SUM(FI14:FI16) -> 0 | ... FM17: =SUM(FM14:FM16) -> 0 | FN17: =+SUBTOTAL(9,FB17:FM17) -> 0 | FP17: =SUM(FP14:FP16) -> 0 | FQ17: =SUM(FQ14:FQ16) -> 0 | FR17: =SUM(FR14:FR16) -> 0 | FS17: =SUM(FS14:FS16) -> 0 | FT17: =SUM(FT14:FT16) -> 0 | FU17: =SUM(FU14:FU16) -> 0 | FV17: =SUM(FV14:FV16) -> 0 | FW17: =SUM(FW14:FW16) -> 0 | ... GA17: =SUM(GA14:GA16) -> 0 | GB17: =+SUBTOTAL(9,FP17:GA17) -> 0 | GD17: =SUM(GD14:GD16) -> 0 | GE17: =SUM(GE14:GE16) -> 0 | GF17: =SUM(GF14:GF16) -> 0 | GG17: =SUM(GG14:GG16) -> 0 | GH17: =SUM(GH14:GH16) -> 0 | GI17: =SUM(GI14:GI16) -> 0 | GJ17: =SUM(GJ14:GJ16) -> 0 | GK17: =SUM(GK14:GK16) -> 0 | ... GO17: =SUM(GO14:GO16) -> 0 | GP17: =+SUBTOTAL(9,GD17:GO17) -> 0 | GR17: =SUM(GR14:GR16) -> 0 | GS17: =SUM(GS14:GS16) -> 0 | GT17: =SUM(GT14:GT16) -> 0 | GU17: =SUM(GU14:GU16) -> 0 | GV17: =SUM(GV14:GV16) -> 0 | GW17: =SUM(GW14:GW16) -> 0 | GX17: =SUM(GX14:GX16) -> 0 | GY17: =SUM(GY14:GY16) -> 0 | ... HC17: =SUM(HC14:HC16) -> 0 | HD17: =+SUBTOTAL(9,GR17:HC17) -> 0 | HF17: =SUM(HF14:HF16) -> 0 | HG17: =SUM(HG14:HG16) -> 0 | HH17: =SUM(HH14:HH16) -> 0 | HI17: =SUM(HI14:HI16) -> 0 | HJ17: =SUM(HJ14:HJ16) -> 0 | HK17: =SUM(HK14:HK16) -> 0 | HL17: =SUM(HL14:HL16) -> 0 | HM17: =SUM(HM14:HM16) -> 0 | ... HQ17: =SUM(HQ14:HQ16) -> 0 | HR17: =+SUBTOTAL(9,HF17:HQ17) -> 0 | HT17: =SUM(HT14:HT16) -> 0 | HU17: =SUM(HU14:HU16) -> 0 | HV17: =SUM(HV14:HV16) -> 0 | HW17: =SUM(HW14:HW16) -> 0 | HX17: =SUM(HX14:HX16) -> 0 | HY17: =SUM(HY14:HY16) -> 0 | HZ17: =SUM(HZ14:HZ16) -> 0 | IA17: =SUM(IA14:IA16) -> 0 | ... IE17: =SUM(IE14:IE16) -> 0 | IF17: =+SUBTOTAL(9,HT17:IE17) -> 0 | IH17: =SUM(IH14:IH16) -> 0 | II17: =SUM(II14:II16) -> 0 | IJ17: =SUM(IJ14:IJ16) -> 0 | IK17: =SUM(IK14:IK16) -> 0 | IL17: =SUM(IL14:IL16) -> 0 | IM17: =SUM(IM14:IM16) -> 0 | IN17: =SUM(IN14:IN16) -> 0 | IO17: =SUM(IO14:IO16) -> 0 | ... IS17: =SUM(IS14:IS16) -> 0 | IT17: =+SUBTOTAL(9,IH17:IS17) -> 0 | IV17: =SUM(IV14:IV16) -> 0 | IW17: =SUM(IW14:IW16) -> 0 | IX17: =SUM(IX14:IX16) -> 0 | IY17: =SUM(IY14:IY16) -> 0 | IZ17: =SUM(IZ14:IZ16) -> 0 | JA17: =SUM(JA14:JA16) -> 0 | JB17: =SUM(JB14:JB16) -> 0 | JC17: =SUM(JC14:JC16) -> 0 | ... JG17: =SUM(JG14:JG16) -> 0 | JH17: =+SUBTOTAL(9,IV17:JG17) -> 0 | JJ17: =SUM(JJ14:JJ16) -> 0 | JK17: =SUM(JK14:JK16) -> 0 | JL17: =SUM(JL14:JL16) -> 0 | JM17: =SUM(JM14:JM16) -> 0 | JN17: =SUM(JN14:JN16) -> 0 | JO17: =SUM(JO14:JO16) -> 0 | JP17: =SUM(JP14:JP16) -> 0 | JQ17: =SUM(JQ14:JQ16) -> 0 | ... JU17: =SUM(JU14:JU16) -> 0 | JV17: =+SUBTOTAL(9,JJ17:JU17) -> 0 | JX17: =SUM(JX14:JX16) -> 0 | JY17: =SUM(JY14:JY16) -> 0 | JZ17: =SUM(JZ14:JZ16) -> 0 | KA17: =SUM(KA14:KA16) -> 0 | KB17: =SUM(KB14:KB16) -> 0 | KC17: =SUM(KC14:KC16) -> 0 | KD17: =SUM(KD14:KD16) -> 0 | KE17: =SUM(KE14:KE16) -> 0 | ... KI17: =SUM(KI14:KI16) -> 0 | KJ17: =+SUBTOTAL(9,JX17:KI17) -> 0 | KL17: =SUM(KL14:KL16) -> 0 | KM17: =SUM(KM14:KM16) -> 0 | KN17: =SUM(KN14:KN16) -> 0 | KO17: =SUM(KO14:KO16) -> 0 | KP17: =SUM(KP14:KP16) -> 0 | KQ17: =SUM(KQ14:KQ16) -> 0 | KR17: =SUM(KR14:KR16) -> 0 | KS17: =SUM(KS14:KS16) -> 0 | ... KW17: =SUM(KW14:KW16) -> 0 | KX17: =+SUBTOTAL(9,KL17:KW17) -> 0 | KZ17: =SUM(KZ14:KZ16) -> 0 | LA17: =SUM(LA14:LA16) -> 0 | LB17: =SUM(LB14:LB16) -> 0 | LC17: =SUM(LC14:LC16) -> 0 | LD17: =SUM(LD14:LD16) -> 0 | LE17: =SUM(LE14:LE16) -> 0 | LF17: =SUM(LF14:LF16) -> 0 | LG17: =SUM(LG14:LG16) -> 0 | ... LK17: =SUM(LK14:LK16) -> 0 | LL17: =+SUBTOTAL(9,KZ17:LK17) -> 0 | LN17: =SUM(LN14:LN16) -> 0 | LO17: =SUM(LO14:LO16) -> 0 | LP17: =SUM(LP14:LP16) -> 0 | LQ17: =SUM(LQ14:LQ16) -> 0 | LR17: =SUM(LR14:LR16) -> 0 | LS17: =SUM(LS14:LS16) -> 0 | LT17: =SUM(LT14:LT16) -> 0 | LU17: =SUM(LU14:LU16) -> 0 | ... LY17: =SUM(LY14:LY16) -> 0 | LZ17: =+SUBTOTAL(9,LN17:LY17) -> 0 | MB17: =SUM(MB14:MB16) -> 0 | MC17: =SUM(MC14:MC16) -> 0 | MD17: =SUM(MD14:MD16) -> 0 | ME17: =SUM(ME14:ME16) -> 0 | MF17: =SUM(MF14:MF16) -> 0 | MG17: =SUM(MG14:MG16) -> 0 | MH17: =SUM(MH14:MH16) -> 0 | MI17: =SUM(MI14:MI16) -> 0 | ... MN17: =SUM(MN14:MN16) -> 0
B19: DIRECT COSTS
