Workbook

Sheet SSC Recharge Summary
A1: India Shared Services
A2: 45658 | B2: January, 2025 | D2: 1 | E2: =3+1+7 -> 11 | F2: 1 | G2: 30 | H2: 3 | I2: 3 | J2: =1+1 -> 2 | K2: 15 | L2: 17 | M2: 1 | N2: =18+9 -> 27 | O2: =13+13+1 -> 27 | P2: 1 | Q2: 4 | R2: =1+1 -> 2 | S2: =4+3 -> 7 | T2: 1 | U2: =1+1+2 -> 4 | V2: 1 | W2: =1+1 -> 2 | X2: =2+2+3 -> 7 | Y2: =4+2+7 -> 13 | Z2: 4
D3: CMI | E3: CMI | F3: CMI | N3: GCC +Jibe | R3: Germany | T3: 13th Floor
B4: Business Unit Name | C4: Expense Type | D4: Crew Management | E4: Cruise Management | F4: Accounts | G4: Accounts | H4: Admin | I4: Agency Services | J4: Commercial | K4: Consultancy Services | L4: Environmental Compliance | M4: Environmental Compliance | N4: IT | O4: Procurement | P4: Procurement | Q4: Ship Management | R4: Ship Management | S4: Ship Management | T4: Ship Management | U4: Ship Management | V4: Ship Management | W4: Ship Management | X4: Ship Management | Y4: Ship Management | Z4: Ship Management | AA4: Technical Services | AB4: Ship Management | AC4: Ship Management | AD4: Actual
B5: Division Name | D5: Group Marine HR | E5: Miami Ship Management | F5: CMI Accounts Payables | G5: Fleet Accounts | H5: Administration | I5: Agency Hub | J5: Commercial | K5: Fleet Performance | L5: Carbon Emission Services | M5: Other Environmental Compliance | N5: Group IT | O5: Galleymasters | P5: Sourcing | Q5: Antwerp Dry | R5: Goes Dry | S5: Group Operations | T5: Group Shared Service Center | U5: Hamburg Dry | V5: Hong Kong Dry 1 | W5: JV Ardmore | X5: Singapore Dry | Y5: Singapore Tanker 1 | Z5: Singapore Tanker 2 | AA5: AE Technical Services | AB5: Hong Kong Dry 2 | AC5: Hong Kong Dry 3 | AD5: Total
A7: A | B7: PERSONNEL EXPENSES
B8: Salaries & Wages | C8: Fixed | D8: 6313.72 | E8: 16347.8 | F8: 1643.79 | G8: 29043.29 | H8: 2239.97 | I8: 2256.14 | J8: 7056.17 | K8: 39208.36 | L8: 17844.41 | M8: 4645.25 | N8: 36370.33 | O8: 20535.24 | P8: 3422.24 | Q8: 6549.82 | R8: 1316.03 | S8: 14282.4 | T8: 7330.55 | U8: 3505.1 | V8: 1625.39 | W8: 6195.08 | X8: 15528.55 | Y8: 24979.43 | Z8: 4581.77 | AA8: 826.95 | AB8: 0 | AC8: 0 | AD8: =SUM(D8:AA8) -> 273647.78
B9: Provision for Bonus, Leave & Other Employment Costs | C9: Fixed | D9: 483.74 | E9: 1252.5 | F9: 125.94 | G9: 2233.66 | H9: 171.64 | I9: 172.87 | J9: 540.61 | K9: 3055.21 | L9: 653.74 | M9: 170.33 | N9: 2780.99 | O9: 1596.5 | P9: 262.21 | Q9: 434.51 | R9: 81.59 | S9: 1094.27 | T9: 86.89 | U9: 377.45 | V9: 124.52 | W9: 444.51 | X9: 1198.53 | Y9: 1765.18 | Z9: 626.76 | AA9: 30.32 | AB9: 0 | AC9: 0 | AD9: =SUM(D9:AA9) -> 19764.47
B10: Consultants & Contractors | C10: Fixed | D10: 0 | E10: 0 | F10: 0 | G10: 0 | H10: 0 | I10: 0 | J10: 0 | K10: 0 | L10: 0 | M10: -608.36 | N10: 3344.15 | O10: 0 | P10: 0 | Q10: 0 | R10: 0 | S10: 655.35 | T10: 0 | U10: 0 | V10: 0 | W10: 0 | X10: 0 | Y10: 0 | Z10: 0 | AA10: 0 | AB10: 0 | AC10: 0 | AD10: =SUM(D10:AA10) -> 3391.14
B11: Pension Fund & Social Securities | C11: Fixed | D11: 434.26 | E11: 1017.43 | F11: 94.83 | G11: 1814.75 | H11: 130.79 | I11: 131.66 | J11: 474.57 | K11: 2634.98 | L11: 1247.53 | M11: 349.29 | N11: 2369.94 | O11: 1272.76 | P11: 235.76 | Q11: 431.96 | R11: 79.6 | S11: 945.66 | T11: 522.85 | U11: 195.02 | V11: 93.81 | W11: 422.37 | X11: 1027.41 | Y11: 1671.28 | Z11: 235.91 | AA11: 52.55 | AB11: 0 | AC11: 0 | AD11: =SUM(D11:AA11) -> 17886.97
B12: Staff Allowances & Benefits | C12: Fixed | D12: 36.52 | E12: 1445.56 | F12: 43.99 | G12: 1319.61 | H12: 109.52 | I12: 109.52 | J12: 73.03 | K12: 547.64 | L12: 620.65 | M12: 36.52 | N12: 985.74 | O12: 985.76 | P12: 36.52 | Q12: 146.04 | R12: 73.03 | S12: 255.56 | T12: 36.52 | U12: 146.04 | V12: 36.52 | W12: 73.03 | X12: 255.54 | Y12: 474.61 | Z12: 146.04 | AA12: 36.52 | AB12: 0 | AC12: 0 | AD12: =SUM(D12:AA12) -> 8030.03
B13: Medical Expenses | C13: Variable | D13: 0 | E13: 0 | F13: 0 | G13: 0 | H13: 0 | I13: 0 | J13: 0 | K13: 0 | L13: 0 | M13: 0 | N13: 0 | O13: 0 | P13: 0 | Q13: 0 | R13: 0 | S13: 0 | T13: 0 | U13: 0 | V13: 0 | W13: 0 | X13: 0 | Y13: 0 | Z13: 0 | AA13: 0 | AB13: 0 | AC13: 0 | AD13: =SUM(D13:AA13) -> 0
B14: Staff Recruitment / Relocation | C14: Variable | D14: -0.45 | E14: -5.01 | F14: -0.46 | G14: -13.66 | H14: -1.37 | I14: -1.37 | J14: -0.9 | K14: 24.79 | L14: -7.74 | M14: -0.45 | N14: -1.84 | O14: -12.28 | P14: -0.45 | Q14: -1.82 | R14: 9.53 | S14: -3.19 | T14: 348.58 | U14: 8.63 | V14: -0.45 | W14: -0.9 | X14: -3.18 | Y14: 14.96 | Z14: -1.82 | AA14: -0.45 | AB14: 0 | AC14: 0 | AD14: =SUM(D14:AA14) -> 348.7
B15: Staff Functions | C15: Variable | D15: 37.57 | E15: 413.36 | F15: 37.58 | G15: 1127.39 | H15: 112.74 | I15: 112.74 | J15: 75.14 | K15: 563.68 | L15: 638.84 | M15: 37.57 | N15: 1014.7 | O15: 1014.63 | P15: 37.57 | Q15: 150.32 | R15: 75.14 | S15: 263.06 | T15: 37.57 | U15: 150.3 | V15: 37.57 | W15: 75.14 | X15: 263.04 | Y15: 488.53 | Z15: 150.32 | AA15: 37.57 | AB15: 0 | AC15: 0 | AD15: =SUM(D15:AA15) -> 6952.07
B16: Course & Training | C16: Variable | D16: 0 | E16: 0 | F16: 0 | G16: 0 | H16: 0 | I16: 0 | J16: 0 | K16: 0 | L16: 0 | M16: 0 | N16: 1876.8 | O16: 0 | P16: 0 | Q16: 0 | R16: 0 | S16: 0 | T16: 0 | U16: 0 | V16: 0 | W16: 0 | X16: 0 | Y16: 0 | Z16: 0 | AA16: 0 | AB16: 0 | AC16: 0 | AD16: =SUM(D16:AA16) -> 1876.8
B17: Joint Venture Personnel Cost Recharges | C17: Fixed | D17: 0 | E17: 0 | F17: 0 | G17: 0 | H17: 0 | I17: 0 | J17: 0 | K17: 0 | L17: 0 | M17: 0 | N17: 0 | O17: 0 | P17: 0 | Q17: 0 | R17: 0 | S17: 0 | T17: 0 | U17: 0 | V17: 0 | W17: 0 | X17: 0 | Y17: 0 | Z17: 0 | AA17: 0 | AB17: 0 | AC17: 0 | AD17: =SUM(D17:AA17) -> 0
B18: Intra-group Personnel Cost Recharges | C18: Fixed | D18: 0 | E18: 0 | F18: 0 | G18: 0 | H18: 0 | I18: 0 | J18: 0 | K18: 0 | L18: 0 | M18: 0 | N18: 0 | O18: 0 | P18: 0 | Q18: 0 | R18: 0 | S18: 0 | T18: 0 | U18: 0 | V18: 0 | W18: 0 | X18: 0 | Y18: 0 | Z18: 0 | AA18: 0 | AB18: 0 | AC18: 0 | AD18: =SUM(D18:AA18) -> 0
AD19: =SUM(AD8:AD18) -> 331897.96
A20: B | B20: OFFICE EXPENSES
B21: Rent - Depreciation | C21: Fixed | D21: 131.16383 | E21: 1442.8021 | F21: 131.16383 | G21: 3934.9148 | H21: 393.49148 | I21: 393.49148 | J21: 262.32765 | K21: 1967.4574 | L21: 2229.785 | M21: 131.16383 | N21: 3541.4233 | O21: 3541.4233 | P21: 0 | Q21: 524.6553 | R21: 262.32765 | S21: 918.14678 | T21: 131.16383 | U21: 524.6553 | V21: 131.16383 | W21: 262.32765 | X21: 918.14678 | Y21: 1705.1297 | Z21: 524.6553 | AA21: 124.36981 | AB21: 0 | AC21: 0 | AD21: =SUM(D21:AA21) -> 24127.35
B22: Rent - Lease Interest | C22: Fixed | D22: 0 | E22: 0 | F22: 0 | G22: 0 | H22: 0 | I22: 0 | J22: 0 | K22: 0 | L22: 0 | M22: 0 | N22: 0 | O22: 0 | P22: 0 | Q22: 0 | R22: 0 | S22: 0 | T22: 0 | U22: 0 | V22: 0 | W22: 0 | X22: 0 | Y22: 0 | Z22: 0 | AA22: 0 | AB22: 0 | AC22: 0 | AD22: =SUM(D22:AA22) -> 0
B23: Rates & Management Fees | C23: Fixed | D23: 15.58 | E23: 171.38 | F23: 15.58 | G23: 467.47 | H23: 46.73 | I23: 46.73 | J23: 31.16 | K23: 384.51 | L23: 264.88 | M23: 15.58 | N23: 420.6 | O23: 420.71 | P23: 0 | Q23: 62.3 | R23: 31.16 | S23: 109.04 | T23: 4098.63 | U23: 62.31 | V23: 15.58 | W23: 31.16 | X23: 109.05 | Y23: 202.53 | Z23: 62.3 | AA23: 15.58 | AB23: 0 | AC23: 0 | AD23: =SUM(D23:AA23) -> 7100.55
B24: Light & Power | C24: Fixed | D24: 5.88 | E24: 64.75 | F24: 5.88 | G24: 176.49 | H24: 17.67 | I24: 17.67 | J24: 11.76 | K24: 88.3 | L24: 100.1 | M24: 5.88 | N24: 158.93 | O24: 158.93 | P24: 0 | Q24: 23.54 | R24: 11.76 | S24: 41.2 | T24: 342.85 | U24: 23.54 | V24: 5.88 | W24: 11.76 | X24: 41.21 | Y24: 76.51 | Z24: 23.54 | AA24: 5.88 | AB24: 0 | AC24: 0 | AD24: =SUM(D24:AA24) -> 1419.91
B25: Office Supplies & Cleaning | C25: Variable | D25: 8.04 | E25: 88.46 | F25: 8.05 | G25: 241.37 | H25: 24.13 | I25: 24.13 | J25: 16.08 | K25: 120.65 | L25: 136.72 | M25: 8.04 | N25: 217.14 | O25: 217.13 | P25: 0 | Q25: 32.17 | R25: 16.08 | S25: 56.29 | T25: 8.04 | U25: 32.15 | V25: 8.04 | W25: 16.08 | X25: 56.28 | Y25: 104.54 | Z25: 32.17 | AA25: 8.04 | AB25: 0 | AC25: 0 | AD25: =SUM(D25:AA25) -> 1479.82
B26: Archive Storage / Warehouse | C26: Fixed | D26: 0.56 | E26: 6.14 | F26: 0.56 | G26: 16.83 | H26: 1.67 | I26: 1.67 | J26: 1.11 | K26: 8.39 | L26: 9.5 | M26: 0.56 | N26: 15.08 | O26: 15.08 | P26: 0 | Q26: 2.23 | R26: 1.11 | S26: 3.9 | T26: 0.56 | U26: 2.23 | V26: 0.56 | W26: 1.11 | X26: 3.9 | Y26: 7.25 | Z26: 2.23 | AA26: 0.56 | AB26: 0 | AC26: 0 | AD26: =SUM(D26:AA26) -> 102.79
B27: Office Repairs & Maintenance | C27: Fixed | D27: 2.76 | E27: 30.36 | F27: 2.76 | G27: 82.73 | H27: 8.28 | I27: 8.28 | J27: 5.52 | K27: 37.92 | L27: 46.87 | M27: 2.76 | N27: 74.49 | O27: 74.49 | P27: 0 | Q27: 11.04 | R27: 5.52 | S27: 19.32 | T27: 2.76 | U27: 11.03 | V27: 2.53 | W27: 5.52 | X27: 19.3 | Y27: 35.87 | Z27: 11.04 | AA27: 2.76 | AB27: 0 | AC27: 0 | AD27: =SUM(D27:AA27) -> 503.91
B28: Intra-group rental cost recharges | C28: Fixed | D28: 61.71 | E28: 678.76 | F28: 61.7 | G28: 1851.08 | H28: 185.12 | I28: 185.12 | J28: 123.42 | K28: 925.58 | L28: 1048.99 | M28: 61.71 | N28: 1666.04 | O28: 1666.05 | P28: 0 | Q28: 246.82 | R28: 123.42 | S28: 431.93 | T28: 61.71 | U28: 246.83 | V28: 61.71 | W28: 123.42 | X28: 431.93 | Y28: 802.16 | Z28: 246.82 | AA28: 61.71 | AB28: 0 | AC28: 0 | AD28: =SUM(D28:AA28) -> 11353.74
AD29: =SUM(AD21:AD28) -> 46088.07
A30: C | B30: ADMINISTRATIVE EXPENSES
B31: IT - Software & Applications | C31: Variable | D31: 42.96 | E31: 472.54 | F31: 42.95 | G31: 1288.59 | H31: 128.87 | I31: 128.87 | J31: 85.93 | K31: 644.36 | L31: 730.26 | M31: 42.96 | N31: 1159.84 | O31: 1159.87 | P31: 42.96 | Q31: 171.84 | R31: 85.93 | S31: 300.71 | T31: 42.96 | U31: 171.84 | V31: 42.96 | W31: 85.93 | X31: 300.68 | Y31: 558.45 | Z31: 171.84 | AA31: 42.96 | AB31: 0 | AC31: 0 | AD31: =SUM(D31:AA31) -> 7947.06
B32: IT - Communications | C32: Variable | D32: 22.55 | E32: 248.14 | F32: 23.57 | G32: 707.2 | H32: 76.75 | I32: 67.66 | J32: 45.1 | K32: 175.33 | L32: 392.97 | M32: 22.55 | N32: 690.99 | O32: 641.24 | P32: -6.96 | Q32: 90.22 | R32: 45.1 | S32: 157.88 | T32: 22.55 | U32: 90.2 | V32: 11.68 | W32: 45.1 | X32: 157.86 | Y32: 293.25 | Z32: 90.22 | AA32: 22.55 | AB32: 0 | AC32: 0 | AD32: =SUM(D32:AA32) -> 4133.7
B33: IT - IT Services | C33: Variable | D33: 3.33 | E33: 36.61 | F33: 3.32 | G33: 99.73 | H33: 9.99 | I33: 9.99 | J33: 6.66 | K33: 9.56 | L33: 56.57 | M33: 3.33 | N33: 459.3 | O33: 89.86 | P33: 0.64 | Q33: 13.32 | R33: 6.66 | S33: 23.3 | T33: 3.33 | U33: 13.32 | V33: 0.64 | W33: 6.66 | X33: 23.3 | Y33: 43.27 | Z33: 13.32 | AA33: 3.33 | AB33: 0 | AC33: 0 | AD33: =SUM(D33:AA33) -> 939.34
B34: IT - Network & Infrastructure Services | C34: Variable | D34: 0 | E34: 0 | F34: 0 | G34: 0 | H34: 0 | I34: 0 | J34: 0 | K34: 0 | L34: 0 | M34: 0 | N34: 0 | O34: 0 | P34: 0 | Q34: 0 | R34: 0 | S34: 0 | T34: 0 | U34: 0 | V34: 0 | W34: 0 | X34: 0 | Y34: 0 | Z34: 0 | AA34: 0 | AB34: 0 | AC34: 0 | AD34: =SUM(D34:AA34) -> 0
B35: Insurance | C35: Fixed | D35: 0.26 | E35: 2.77 | F35: 0.25 | G35: 7.51 | H35: 0.75 | I35: 0.75 | J35: 0.51 | K35: 3.78 | L35: 4.29 | M35: 0.26 | N35: 6.82 | O35: 6.82 | P35: 0 | Q35: 1.01 | R35: 0.51 | S35: 1.76 | T35: 114.91 | U35: 1.02 | V35: 0.26 | W35: 0.51 | X35: 1.77 | Y35: 3.28 | Z35: 1.01 | AA35: 0.26 | AB35: 0 | AC35: 0 | AD35: =SUM(D35:AA35) -> 161.07
B36: Marketing, Branding & Communications | C36: Variable | D36: 0 | E36: 0 | F36: 0 | G36: 0 | H36: 0 | I36: 0 | J36: 0 | K36: 0 | L36: 0 | M36: 0 | N36: 0 | O36: 0 | P36: 0 | Q36: 0 | R36: 0 | S36: 0 | T36: 0 | U36: 0 | V36: 0 | W36: 0 | X36: 0 | Y36: 0 | Z36: 0 | AA36: 0 | AB36: 0 | AC36: 0 | AD36: =SUM(D36:AA36) -> 0
B37: Overseas Travelling | C37: Variable | D37: 2757.23 | E37: 0 | F37: 0 | G37: 0 | H37: 0 | I37: 0 | J37: 0 | K37: 673.8 | L37: 0 | M37: 0 | N37: 0 | O37: 0 | P37: 0 | Q37: 0 | R37: 0 | S37: 0 | T37: 2970.37 | U37: 0 | V37: 384.24 | W37: 0 | X37: 0 | Y37: 62.15 | Z37: 0 | AA37: 0 | AB37: 0 | AC37: 0 | AD37: =SUM(D37:AA37) -> 6847.79
B38: Local Travelling | C38: Variable | D38: 21.39 | E38: 594.86 | F38: 18.25 | G38: 547.57 | H38: 100.96 | I38: 64.17 | J38: 179.19 | K38: 4.94 | L38: 318.94 | M38: 21.39 | N38: 549.07 | O38: 549.08 | P38: 0.01 | Q38: 85.56 | R38: 42.78 | S38: 157.08 | T38: 336.26 | U38: 85.57 | V38: -7.78 | W38: 42.78 | X38: 149.75 | Y38: 278.07 | Z38: 85.56 | AA38: 21.39 | AB38: 0 | AC38: 0 | AD38: =SUM(D38:AA38) -> 4246.84
B39: ISSC Team | C39: Variable | D39: 0 | E39: 0 | F39: 0 | G39: 0 | H39: 0 | I39: 0 | J39: 0 | K39: 0 | L39: 0 | M39: 0 | N39: 0 | O39: 0 | P39: 0 | Q39: 0 | R39: 0 | S39: 0 | T39: 0 | U39: 0 | V39: 0 | W39: 0 | X39: 0 | Y39: 0 | Z39: 0 | AD39: =SUM(D39:AA39) -> 0
B40: Motor Car Expenses | C40: Variable | D40: 198.46 | E40: -138.76 | F40: 2.5 | G40: 74.97 | H40: 0 | I40: 0 | J40: 0 | K40: 0 | L40: 0 | M40: 0 | N40: 0 | O40: 0 | P40: 0 | Q40: 0 | R40: 0 | S40: 0 | T40: 543.23 | U40: 0 | V40: 0 | W40: 0 | X40: 0 | Y40: 0 | Z40: 0 | AA40: 0 | AB40: 0 | AC40: 0 | AD40: =SUM(D40:AA40) -> 680.4
B41: Entertainment | C41: Variable | D41: 0 | E41: 0 | F41: 0 | G41: 0 | H41: 0 | I41: 0 | J41: 0 | K41: 0 | L41: 0 | M41: 0 | N41: 0 | O41: 0 | P41: 0 | Q41: 0 | R41: 0 | S41: 40.53 | T41: 56.99 | U41: 0 | V41: 0 | W41: 0 | X41: 0 | Y41: 0 | Z41: 0 | AA41: 0 | AB41: 0 | AC41: 0 | AD41: =SUM(D41:AA41) -> 97.52
...

Sheet ISSC spend kpi
A1: Months | B1: Category 1 | C1: Head counts | D1: 1. Total ISSC Spend | E1: 2. Spend vs. Budget Variance | F1: 3. Fixed vs. Variable Cost Ratio | G1: 4. Cost Per FTE (Desk Cost) | H1: Category 2 | I1: 1. Employee Cost as % of Total ISSC Spend | J1: 2. Training Cost per Employee | K1: Category 3 | L1: 1. IT Spend as % of Total ISSC Spend | M1: Category 4 | N1: 1. Total Facility Spend | O1: 2. Facility Spend as % of Total Spend | P1: 3. Average Cost per Employee | Q1: 4. Space Utilization | R1: 5. Admin Cost per FTE | S1: Category 5 | T1: 1. Travel Spend per Employee | U1: 2. Overall Travel Cost | V1: 3.Travel Cost as % of Total ISSC Spend
A3: 45658 | B3: Overall Cost Insights | C3: =+'SSC Recharge Summary'!AD77 -> 185 | D3: =+'SSC Recharge Summary'!AD72 -> 440161.1 | E3: =+D3-'P& L budget 2025'!MB259 -> 1805.5196 | F3: ='SSC Recharge Summary'!AD73&" "&":"&" "&'SSC Recharge Summary'!AD74 -> 0.91 : 0.09 | G3: =D3/C3 -> 2379.2492 | H3: Employee-Related Costs | I3: =SUM('SSC Recharge Summary'!AD8:AD18)/D3 -> 0.75403747 | J3: - | K3: IT & Technology Costs | L3: {=SUM('SSC Recharge Summary'!AD31:AD34/'ISSC spend kpi'!D3)} -> 0.029580306 | M3: Facility & Office Costs | N3: =SUM('SSC Recharge Summary'!AD21:AD28) -> 46088.07 | O3: =N3/D3 -> 0.10470728 | P3: =N3/C3 -> 249.1247 | Q3: - | R3: =SUM('SSC Recharge Summary'!AD35:AD52)/C3 -> 90.414634 | S3: Travel and Transportation Costs | T3: =SUM('SSC Recharge Summary'!AD37:AD38)/C3 -> 59.970973 | U3: =SUM('SSC Recharge Summary'!AD37:AD38) -> 11094.63 | V3: ='[1]ISSC Spend_KPI''s'!$F$27 -> 0.02520584
A4: 45689 | B4: Overall Cost Insights | C4: =+'SSC Recharge Summary'!AD154 -> 189 | D4: =+'SSC Recharge Summary'!AD149 -> 448023.2 | H4: Employee-Related Costs | K4: IT & Technology Costs | L4: {=SUM('SSC Recharge Summary'!AD121:AD123/D4)} -> 0.026190496 | M4: Facility & Office Costs | S4: Travel and Transportation Costs
A5: 45717 | B5: Overall Cost Insights | H5: Employee-Related Costs | K5: IT & Technology Costs | M5: Facility & Office Costs | S5: Travel and Transportation Costs
A6: 45748 | B6: Overall Cost Insights | H6: Employee-Related Costs | K6: IT & Technology Costs | M6: Facility & Office Costs | S6: Travel and Transportation Costs
A7: 45778 | B7: Overall Cost Insights | H7: Employee-Related Costs | K7: IT & Technology Costs | M7: Facility & Office Costs | S7: Travel and Transportation Costs
A8: 45809 | B8: Overall Cost Insights | H8: Employee-Related Costs | K8: IT & Technology Costs | M8: Facility & Office Costs | S8: Travel and Transportation Costs
A9: 45839 | B9: Overall Cost Insights | H9: Employee-Related Costs | K9: IT & Technology Costs | M9: Facility & Office Costs | S9: Travel and Transportation Costs
A10: 45870 | B10: Overall Cost Insights | H10: Employee-Related Costs | K10: IT & Technology Costs | M10: Facility & Office Costs | S10: Travel and Transportation Costs
A11: 45901 | B11: Overall Cost Insights | H11: Employee-Related Costs | K11: IT & Technology Costs | M11: Facility & Office Costs | S11: Travel and Transportation Costs
A12: 45931 | B12: Overall Cost Insights | H12: Employee-Related Costs | K12: IT & Technology Costs | M12: Facility & Office Costs | S12: Travel and Transportation Costs
A13: 45962 | B13: Overall Cost Insights | H13: Employee-Related Costs | K13: IT & Technology Costs | M13: Facility & Office Costs | S13: Travel and Transportation Costs
A14: 45992 | B14: Overall Cost Insights | H14: Employee-Related Costs | K14: IT & Technology Costs | M14: Facility & Office Costs | S14: Travel and Transportation Costs

Sheet P& L budget 2025
B1: ANGLO-EASTERN MARITIME SERVICES PRIVATE LIMITED | P1: =+P6 -> Budget-2025 | AD1: =+AD6 -> Budget-2025 | AR1: =+AR6 -> Budget-2025 | BF1: =+BF6 -> Budget-2025 | BT1: =+BT6 -> #REF! | CH1: =+CH6 -> #REF! | CV1: =+CV6 -> #REF! | DJ1: =+DJ6 -> #REF! | DX1: =+DX6 -> #REF! | EL1: =+EL6 -> #REF! | EZ1: =+EZ6 -> #REF! | FN1: =+FN6 -> #REF! | GB1: =+GB6 -> #REF! | GP1: =+GP6 -> #REF! | HD1: =+HD6 -> Total | HR1: =+HR6 -> #REF! | IF1: =+IF6 -> #REF! | IT1: =+IT6 -> #REF! | JH1: =+JH6 -> #REF! | JV1: =+JV6 -> #REF! | KJ1: =+KJ6 -> #REF! | KX1: =+KX6 -> Total | LL1: =+LL6 -> Total | LZ1: =+LZ6 -> Total | MB1: =+LZ1 -> Total | MC1: =+MB1 -> Total | MD1: =+MC1 -> Total | ME1: =+MD1 -> Total | MF1: =+ME1 -> Total | MG1: =+MF1 -> Total | MH1: =+MG1 -> Total | MI1: =+MH1 -> Total | MJ1: =+MI1 -> Total | ... MN1: =+MM1 -> Total
B2: Budget 2025 | P2: 1 | AD2: 2 | AR2: 3 | BF2: 4 | BT2: 6 | CH2: 8 | CV2: 11 | DJ2: 12 | DX2: 13 | EL2: 14 | EZ2: 15 | FN2: 16 | GB2: 17 | GP2: 19 | HD2: 30 | HR2: 20 | IF2: 21 | IT2: 22 | JH2: 23 | JV2: 24 | KJ2: 25 | KX2: 28 | LL2: 29 | LZ2: 31
B3: BU | D3: Accounts | P3: =+D3 -> Accounts | R3: Admin | AD3: =+R3 -> Admin | AF3: Agency Services | AR3: =AF3 -> Agency Services | AT3: Commercial | BF3: =AT3 -> Commercial | BH3: Consultancy Services | BT3: =+BH3 -> Consultancy Services | BV3: Crew Management | CH3: =+BV3 -> Crew Management | CJ3: Cruise Management | CV3: =+CJ3 -> Cruise Management | CX3: IT | DJ3: =+CX3 -> IT | DL3: Procurement | DX3: =+DL3 -> Procurement | DZ3: Procurement | EL3: =+DZ3 -> Procurement | EN3: Ship Management | EZ3: =+EN3 -> Ship Management | FB3: Ship Management | FN3: =+FB3 -> Ship Management | FP3: Ship Management | GB3: =+FP3 -> Ship Management | GD3: Ship Management | GP3: =+GD3 -> Ship Management | GR3: Vacant Seats | HD3: =+GR3 -> Vacant Seats | HF3: Ship Management | HR3: =+HF3 -> Ship Management | HT3: Ship Management | IF3: =+HT3 -> Ship Management | IH3: Ship Management | IT3: =+IH3 -> Ship Management | IV3: Ship Management | JH3: =+IV3 -> Ship Management | JJ3: Ship Management | JV3: =+JJ3 -> Ship Management | JX3: Ship Management | KJ3: =+JX3 -> Ship Management | KL3: Accounts | KX3: =+KL3 -> Accounts | KZ3: Accounts | LL3: =+KZ3 -> Accounts | LZ3: =+LN3 -> 0 | MB3: =LN6 -> 45688 | MC3: =LO6 -> 45716 | MD3: =LP6 -> 45747 | ME3: =LQ6 -> 45777 | MF3: =LR6 -> 45808 | MG3: =LS6 -> 45838 | MH3: =LT6 -> 45869 | MI3: =LU6 -> 45900 | ... MN3: =LZ6 -> Total
B4: Division | D4: Fleet Accounts | P4: =+D4 -> Fleet Accounts | R4: Administration | AD4: =+R4 -> Administration | AF4: Agency Hub | AR4: =AF4 -> Agency Hub | AT4: Commercial | BF4: =AT4 -> Commercial | BH4: Fleet Performance | BT4: =+BH4 -> Fleet Performance | BV4: Group Marine HR | CH4: =+BV4 -> Group Marine HR | CJ4: Miami Ship Management | CV4: =+CJ4 -> Miami Ship Management | CX4: Group IT | DJ4: =+CX4 -> Group IT | DL4: Galleymasters | DX4: =+DL4 -> Galleymasters | DZ4: Sourcing | EL4: =+DZ4 -> Sourcing | EN4: Antwerp Dry | EZ4: =+EN4 -> Antwerp Dry | FB4: Goes Dry | FN4: =+FB4 -> Goes Dry | FP4: Group Operations | GB4: =+FP4 -> Group Operations | GD4: Group Shared Service Center | GP4: =+GD4 -> Group Shared Service Center | GR4: Vacant Seats | HD4: =+GR4 -> Vacant Seats | HF4: Hamburg Dry | HR4: =+HF4 -> Hamburg Dry | HT4: Hong Kong Dry 1 | IF4: =+HT4 -> Hong Kong Dry 1 | IH4: JV Ardmore | IT4: =+IH4 -> JV Ardmore | IV4: Singapore Dry | JH4: =+IV4 -> Singapore Dry | JJ4: Singapore Tanker 1 | JV4: =+JJ4 -> Singapore Tanker 1 | JX4: Singapore Tanker 2 | KJ4: =+JX4 -> Singapore Tanker 2 | KL4: Accounts Payables | KX4: =+KL4 -> Accounts Payables | KZ4: CMI Accounts Payables | LL4: =+KZ4 -> CMI Accounts Payables | LZ4: =+LN4 -> 0 | MB4: All Divisions | MC4: =MB4 -> All Divisions | MD4: =MC4 -> All Divisions | ME4: =MD4 -> All Divisions | MF4: =ME4 -> All Divisions | MG4: =MF4 -> All Divisions | MH4: =MG4 -> All Divisions | MI4: =MH4 -> All Divisions | MJ4: =MI4 -> All Divisions | ... MN4: =MM4 -> All Divisions
B5: Amount (INR) | D5: INR | E5: INR | F5: INR | G5: INR | H5: INR | I5: INR | J5: INR | K5: INR | L5: INR | M5: INR | N5: INR | O5: INR | P5: INR | R5: INR | S5: INR | T5: INR | U5: INR | V5: INR | W5: INR | X5: INR | Y5: INR | Z5: INR | AA5: INR | AB5: INR | AC5: INR | AD5: INR | AF5: INR | AG5: INR | AH5: INR | AI5: INR | AJ5: INR | AK5: INR | AL5: INR | AM5: INR | AN5: INR | AO5: INR | AP5: INR | AQ5: INR | AR5: INR | AT5: INR | AU5: INR | AV5: INR | AW5: INR | AX5: INR | AY5: INR | AZ5: INR | BA5: INR | BB5: INR | BC5: INR | BD5: INR | BE5: INR | BF5: INR | BH5: INR | BI5: INR | BJ5: INR | BK5: INR | BL5: INR | BM5: INR | BN5: INR | BO5: INR | BP5: INR | BQ5: INR | BR5: INR | BS5: INR | BT5: INR | BV5: INR | BW5: INR | BX5: INR | BY5: INR | BZ5: INR | CA5: INR | CB5: INR | CC5: INR | CD5: INR | CE5: INR | CF5: INR | CG5: INR | CH5: INR | CJ5: INR | CK5: INR | CL5: INR | CM5: INR | CN5: INR | CO5: INR | CP5: INR | CQ5: INR | CR5: INR | CS5: INR | CT5: INR | CU5: INR | CV5: INR | CX5: INR | CY5: INR | CZ5: INR | DA5: INR | DB5: INR | DC5: INR | DD5: INR | DE5: INR | DF5: INR | DG5: INR | DH5: INR | DI5: INR | DJ5: INR | DL5: INR | DM5: INR | DN5: INR | DO5: INR | DP5: INR | DQ5: INR | DR5: INR | DS5: INR | DT5: INR | DU5: INR | DV5: INR | DW5: INR | DX5: INR | DZ5: INR | EA5: INR | EB5: INR | EC5: INR | ED5: INR | EE5: INR | EF5: INR | EG5: INR | EH5: INR | EI5: INR | EJ5: INR | EK5: INR | EL5: INR | EN5: INR | EO5: INR | EP5: INR | EQ5: INR | ER5: INR | ES5: INR | ET5: INR | EU5: INR | EV5: INR | EW5: INR | EX5: INR | EY5: INR | EZ5: INR | FB5: INR | FC5: INR | FD5: INR | FE5: INR | FF5: INR | FG5: INR | FH5: INR | FI5: INR | FJ5: INR | FK5: INR | FL5: INR | FM5: INR | FN5: INR | FP5: INR | FQ5: INR | FR5: INR | FS5: INR | FT5: INR | FU5: INR | FV5: INR | FW5: INR | FX5: INR | FY5: INR | FZ5: INR | GA5: INR | GB5: INR | GD5: INR | GE5: INR | GF5: INR | GG5: INR | GH5: INR | GI5: INR | GJ5: INR | GK5: INR | GL5: INR | GM5: INR | GN5: INR | GO5: INR | GP5: INR | GR5: INR | GS5: INR | GT5: INR | GU5: INR | GV5: INR | GW5: INR | GX5: INR | GY5: INR | GZ5: INR | HA5: INR | HB5: INR | HC5: INR | HD5: INR | HF5: INR | HG5: INR | HH5: INR | HI5: INR | HJ5: INR | HK5: INR | HL5: INR | HM5: INR | HN5: INR | HO5: INR | HP5: INR | HQ5: INR | HR5: INR | HT5: INR | HU5: INR | HV5: INR | HW5: INR | HX5: INR | HY5: INR | HZ5: INR | IA5: INR | IB5: INR | IC5: INR | ID5: INR | IE5: INR | IF5: INR | IH5: INR | II5: INR | IJ5: INR | IK5: INR | IL5: INR | IM5: INR | IN5: INR | IO5: INR | IP5: INR | IQ5: INR | IR5: INR | IS5: INR | IT5: INR | IV5: INR | IW5: INR | IX5: INR | IY5: INR | IZ5: INR | JA5: INR | JB5: INR | JC5: INR | JD5: INR | JE5: INR | JF5: INR | JG5: INR | JH5: INR | JJ5: INR | JK5: INR | JL5: INR | JM5: INR | JN5: INR | JO5: INR | JP5: INR | JQ5: INR | JR5: INR | JS5: INR | JT5: INR | JU5: INR | JV5: INR | JX5: INR | JY5: INR | JZ5: INR | KA5: INR | KB5: INR | KC5: INR | KD5: INR | KE5: INR | KF5: INR | KG5: INR | KH5: INR | KI5: INR | KJ5: INR | KL5: INR | KM5: INR | KN5: INR | KO5: INR | KP5: INR | KQ5: INR | KR5: INR | KS5: INR | KT5: INR | KU5: INR | KV5: INR | KW5: INR | KX5: INR | KZ5: INR | LA5: INR | LB5: INR | LC5: INR | LD5: INR | LE5: INR | LF5: INR | LG5: INR | LH5: INR | LI5: INR | LJ5: INR | LK5: INR | LL5: INR | LN5: INR | LO5: INR | LP5: INR | LQ5: INR | LR5: INR | LS5: INR | LT5: INR | LU5: INR | LV5: INR | LW5: INR | LX5: INR | LY5: INR | LZ5: INR | MB5: INR | MC5: =MB5 -> INR | MD5: =MC5 -> INR | ME5: =MD5 -> INR | MF5: =ME5 -> INR | MG5: =MF5 -> INR | MH5: =MG5 -> INR | MI5: =MH5 -> INR | MJ5: =MI5 -> INR | ... MN5: =MM5 -> INR
B6: Month (2025) | D6: 45688 | E6: 45716 | F6: 45747 | G6: 45777 | H6: 45808 | I6: 45838 | J6: 45869 | K6: 45900 | L6: 45930 | M6: 45961 | N6: 45991 | O6: 46022 | P6: Budget-2025 | R6: 45688 | S6: 45716 | T6: 45747 | U6: 45777 | V6: 45808 | W6: 45838 | X6: 45869 | Y6: 45900 | Z6: 45930 | AA6: 45961 | AB6: 45991 | AC6: 46022 | AD6: =+P6 -> Budget-2025 | AF6: 45688 | AG6: 45716 | AH6: 45747 | AI6: 45777 | AJ6: 45808 | AK6: 45838 | AL6: 45869 | AM6: 45900 | AN6: 45930 | AO6: 45961 | AP6: 45991 | AQ6: 46022 | AR6: =AD6 -> Budget-2025 | AT6: 45688 | AU6: 45716 | AV6: 45747 | AW6: 45777 | AX6: 45808 | AY6: 45838 | AZ6: 45869 | BA6: 45900 | BB6: 45930 | BC6: 45961 | BD6: 45991 | BE6: 46022 | BF6: =AR6 -> Budget-2025 | BH6: 45688 | BI6: 45716 | BJ6: 45747 | BK6: 45777 | BL6: 45808 | BM6: 45838 | BN6: 45869 | BO6: 45900 | BP6: 45930 | BQ6: 45961 | BR6: 45991 | BS6: 46022 | BT6: =+#REF! -> #REF! | BV6: 45688 | BW6: 45716 | BX6: 45747 | BY6: 45777 | BZ6: 45808 | CA6: 45838 | CB6: 45869 | CC6: 45900 | CD6: 45930 | CE6: 45961 | CF6: 45991 | CG6: 46022 | CH6: =+#REF! -> #REF! | CJ6: 45688 | CK6: 45716 | CL6: 45747 | CM6: 45777 | CN6: 45808 | CO6: 45838 | CP6: 45869 | CQ6: 45900 | CR6: 45930 | CS6: 45961 | CT6: 45991 | CU6: 46022 | CV6: =+#REF! -> #REF! | CX6: 45688 | CY6: 45716 | CZ6: 45747 | DA6: 45777 | DB6: 45808 | DC6: 45838 | DD6: 45869 | DE6: 45900 | DF6: 45930 | DG6: 45961 | DH6: 45991 | DI6: 46022 | DJ6: =+CV6 -> #REF! | DL6: 45688 | DM6: 45716 | DN6: 45747 | DO6: 45777 | DP6: 45808 | DQ6: 45838 | DR6: 45869 | DS6: 45900 | DT6: 45930 | DU6: 45961 | DV6: 45991 | DW6: 46022 | DX6: =+DJ6 -> #REF! | DZ6: 45688 | EA6: 45716 | EB6: 45747 | EC6: 45777 | ED6: 45808 | EE6: 45838 | EF6: 45869 | EG6: 45900 | EH6: 45930 | EI6: 45961 | EJ6: 45991 | EK6: 46022 | EL6: =+DX6 -> #REF! | EN6: 45688 | EO6: 45716 | EP6: 45747 | EQ6: 45777 | ER6: 45808 | ES6: 45838 | ET6: 45869 | EU6: 45900 | EV6: 45930 | EW6: 45961 | EX6: 45991 | EY6: 46022 | EZ6: =+EL6 -> #REF! | FB6: 45688 | FC6: 45716 | FD6: 45747 | FE6: 45777 | FF6: 45808 | FG6: 45838 | FH6: 45869 | FI6: 45900 | FJ6: 45930 | FK6: 45961 | FL6: 45991 | FM6: 46022 | FN6: =+EZ6 -> #REF! | FP6: 45688 | FQ6: 45716 | FR6: 45747 | FS6: 45777 | FT6: 45808 | FU6: 45838 | FV6: 45869 | FW6: 45900 | FX6: 45930 | FY6: 45961 | FZ6: 45991 | GA6: 46022 | GB6: =+FN6 -> #REF! | GD6: 45688 | GE6: 45716 | GF6: 45747 | GG6: 45777 | GH6: 45808 | GI6: 45838 | GJ6: 45869 | GK6: 45900 | GL6: 45930 | GM6: 45961 | GN6: 45991 | GO6: 46022 | GP6: =+#REF! -> #REF! | GR6: 45688 | GS6: 45716 | GT6: 45747 | GU6: 45777 | GV6: 45808 | GW6: 45838 | GX6: 45869 | GY6: 45900 | GZ6: 45930 | HA6: 45961 | HB6: 45991 | HC6: 46022 | HD6: =+LL6 -> Total | HF6: 45688 | HG6: 45716 | HH6: 45747 | HI6: 45777 | HJ6: 45808 | HK6: 45838 | HL6: 45869 | HM6: 45900 | HN6: 45930 | HO6: 45961 | HP6: 45991 | HQ6: 46022 | HR6: =+GP6 -> #REF! | HT6: 45688 | HU6: 45716 | HV6: 45747 | HW6: 45777 | HX6: 45808 | HY6: 45838 | HZ6: 45869 | IA6: 45900 | IB6: 45930 | IC6: 45961 | ID6: 45991 | IE6: 46022 | IF6: =+HR6 -> #REF! | IH6: 45688 | II6: 45716 | IJ6: 45747 | IK6: 45777 | IL6: 45808 | IM6: 45838 | IN6: 45869 | IO6: 45900 | IP6: 45930 | IQ6: 45961 | IR6: 45991 | IS6: 46022 | IT6: =+IF6 -> #REF! | IV6: 45688 | IW6: 45716 | IX6: 45747 | IY6: 45777 | IZ6: 45808 | JA6: 45838 | JB6: 45869 | JC6: 45900 | JD6: 45930 | JE6: 45961 | JF6: 45991 | JG6: 46022 | JH6: =+IT6 -> #REF! | JJ6: 45688 | JK6: 45716 | JL6: 45747 | JM6: 45777 | JN6: 45808 | JO6: 45838 | JP6: 45869 | JQ6: 45900 | JR6: 45930 | JS6: 45961 | JT6: 45991 | JU6: 46022 | JV6: =+JH6 -> #REF! | JX6: 45688 | JY6: 45716 | JZ6: 45747 | KA6: 45777 | KB6: 45808 | KC6: 45838 | KD6: 45869 | KE6: 45900 | KF6: 45930 | KG6: 45961 | KH6: 45991 | KI6: 46022 | KJ6: =+JV6 -> #REF! | KL6: 45688 | KM6: 45716 | KN6: 45747 | KO6: 45777 | KP6: 45808 | KQ6: 45838 | KR6: 45869 | KS6: 45900 | KT6: 45930 | KU6: 45961 | KV6: 45991 | KW6: 46022 | KX6: Total | KZ6: 45688 | LA6: 45716 | LB6: 45747 | LC6: 45777 | LD6: 45808 | LE6: 45838 | LF6: 45869 | LG6: 45900 | LH6: 45930 | LI6: 45961 | LJ6: 45991 | LK6: 46022 | LL6: =+KX6 -> Total | LN6: 45688 | LO6: 45716 | LP6: 45747 | LQ6: 45777 | LR6: 45808 | LS6: 45838 | LT6: 45869 | LU6: 45900 | LV6: 45930 | LW6: 45961 | LX6: 45991 | LY6: 46022 | LZ6: =+HD6 -> Total | MB6: Total | MC6: =MB6 -> Total | MD6: =MC6 -> Total | ME6: =MD6 -> Total | MF6: =ME6 -> Total | MG6: =MF6 -> Total | MH6: =MG6 -> Total | MI6: =MH6 -> Total | MJ6: =MI6 -> Total | ... MN6: =MM6 -> Total
B7: Unique BU-Division Name | D7: Accounts-Fleet Accounts | E7: Accounts-Fleet Accounts | F7: Accounts-Fleet Accounts | G7: Accounts-Fleet Accounts | H7: Accounts-Fleet Accounts | I7: Accounts-Fleet Accounts | J7: Accounts-Fleet Accounts | K7: Accounts-Fleet Accounts | L7: Accounts-Fleet Accounts | M7: Accounts-Fleet Accounts | N7: Accounts-Fleet Accounts | O7: Accounts-Fleet Accounts | P7: Accounts-Fleet Accounts | R7: Admin-Administration | S7: Admin-Administration | T7: Admin-Administration | U7: Admin-Administration | V7: Admin-Administration | W7: Admin-Administration | X7: Admin-Administration | Y7: Admin-Administration | Z7: Admin-Administration | AA7: Admin-Administration | AB7: Admin-Administration | AC7: Admin-Administration | AD7: Admin-Administration | AF7: Agency Services-Agency Hub | AG7: Agency Services-Agency Hub | AH7: Agency Services-Agency Hub | AI7: Agency Services-Agency Hub | AJ7: Agency Services-Agency Hub | AK7: Agency Services-Agency Hub | AL7: Agency Services-Agency Hub | AM7: Agency Services-Agency Hub | AN7: Agency Services-Agency Hub | AO7: Agency Services-Agency Hub | AP7: Agency Services-Agency Hub | AQ7: Agency Services-Agency Hub | AR7: Agency Services-Agency Hub | AT7: Commercial-Commercial | AU7: Commercial-Commercial | AV7: Commercial-Commercial | AW7: Commercial-Commercial | AX7: Commercial-Commercial | AY7: Commercial-Commercial | AZ7: Commercial-Commercial | BA7: Commercial-Commercial | BB7: Commercial-Commercial | BC7: Commercial-Commercial | BD7: Commercial-Commercial | BE7: Commercial-Commercial | BF7: Commercial-Commercial | BH7: Consultancy Services-Fleet Performance | BI7: Consultancy Services-Fleet Performance | BJ7: Consultancy Services-Fleet Performance | BK7: Consultancy Services-Fleet Performance | BL7: Consultancy Services-Fleet Performance | BM7: Consultancy Services-Fleet Performance | BN7: Consultancy Services-Fleet Performance | BO7: Consultancy Services-Fleet Performance | BP7: Consultancy Services-Fleet Performance | BQ7: Consultancy Services-Fleet Performance | BR7: Consultancy Services-Fleet Performance | BS7: Consultancy Services-Fleet Performance | BT7: Consultancy Services-Fleet Performance | BV7: Crew Management-Group Marine HR | BW7: Crew Management-Group Marine HR | BX7: Crew Management-Group Marine HR | BY7: Crew Management-Group Marine HR | BZ7: Crew Management-Group Marine HR | CA7: Crew Management-Group Marine HR | CB7: Crew Management-Group Marine HR | CC7: Crew Management-Group Marine HR | CD7: Crew Management-Group Marine HR | CE7: Crew Management-Group Marine HR | CF7: Crew Management-Group Marine HR | CG7: Crew Management-Group Marine HR | CH7: Crew Management-Group Marine HR | CJ7: Cruise Management-Miami Ship Management | CK7: Cruise Management-Miami Ship Management | CL7: Cruise Management-Miami Ship Management | CM7: Cruise Management-Miami Ship Management | CN7: Cruise Management-Miami Ship Management | CO7: Cruise Management-Miami Ship Management | CP7: Cruise Management-Miami Ship Management | CQ7: Cruise Management-Miami Ship Management | CR7: Cruise Management-Miami Ship Management | CS7: Cruise Management-Miami Ship Management | CT7: Cruise Management-Miami Ship Management | CU7: Cruise Management-Miami Ship Management | CV7: Cruise Management-Miami Ship Management | CX7: IT-Group IT | CY7: IT-Group IT | CZ7: IT-Group IT | DA7: IT-Group IT | DB7: IT-Group IT | DC7: IT-Group IT | DD7: IT-Group IT | DE7: IT-Group IT | DF7: IT-Group IT | DG7: IT-Group IT | DH7: IT-Group IT | DI7: IT-Group IT | DJ7: IT-Group IT | DL7: Procurement-Galleymasters | DM7: Procurement-Galleymasters | DN7: Procurement-Galleymasters | DO7: Procurement-Galleymasters | DP7: Procurement-Galleymasters | DQ7: Procurement-Galleymasters | DR7: Procurement-Galleymasters | DS7: Procurement-Galleymasters | DT7: Procurement-Galleymasters | DU7: Procurement-Galleymasters | DV7: Procurement-Galleymasters | DW7: Procurement-Galleymasters | DX7: Procurement-Galleymasters | DZ7: Procurement-Sourcing | EA7: Procurement-Sourcing | EB7: Procurement-Sourcing | EC7: Procurement-Sourcing | ED7: Procurement-Sourcing | EE7: Procurement-Sourcing | EF7: Procurement-Sourcing | EG7: Procurement-Sourcing | EH7: Procurement-Sourcing | EI7: Procurement-Sourcing | EJ7: Procurement-Sourcing | EK7: Procurement-Sourcing | EL7: Procurement-Sourcing | EN7: Ship Management-Antwerp Dry | EO7: Ship Management-Antwerp Dry | EP7: Ship Management-Antwerp Dry | EQ7: Ship Management-Antwerp Dry | ER7: Ship Management-Antwerp Dry | ES7: Ship Management-Antwerp Dry | ET7: Ship Management-Antwerp Dry | EU7: Ship Management-Antwerp Dry | EV7: Ship Management-Antwerp Dry | EW7: Ship Management-Antwerp Dry | EX7: Ship Management-Antwerp Dry | EY7: Ship Management-Antwerp Dry | EZ7: Ship Management-Antwerp Dry | FB7: Ship Management-Goes Dry | FC7: Ship Management-Goes Dry | FD7: Ship Management-Goes Dry | FE7: Ship Management-Goes Dry | FF7: Ship Management-Goes Dry | FG7: Ship Management-Goes Dry | FH7: Ship Management-Goes Dry | FI7: Ship Management-Goes Dry | FJ7: Ship Management-Goes Dry | FK7: Ship Management-Goes Dry | FL7: Ship Management-Goes Dry | FM7: Ship Management-Goes Dry | FN7: Ship Management-Goes Dry | FP7: Ship Management-Group Operations | FQ7: Ship Management-Group Operations | FR7: Ship Management-Group Operations | FS7: Ship Management-Group Operations | FT7: Ship Management-Group Operations | FU7: Ship Management-Group Operations | FV7: Ship Management-Group Operations | FW7: Ship Management-Group Operations | FX7: Ship Management-Group Operations | FY7: Ship Management-Group Operations | FZ7: Ship Management-Group Operations | GA7: Ship Management-Group Operations | GB7: Ship Management-Group Operations | GD7: Ship Management-Group Shared Service Center | GE7: Ship Management-Group Shared Service Center | GF7: Ship Management-Group Shared Service Center | GG7: Ship Management-Group Shared Service Center | GH7: Ship Management-Group Shared Service Center | GI7: Ship Management-Group Shared Service Center | GJ7: Ship Management-Group Shared Service Center | GK7: Ship Management-Group Shared Service Center | GL7: Ship Management-Group Shared Service Center | GM7: Ship Management-Group Shared Service Center | GN7: Ship Management-Group Shared Service Center | GO7: Ship Management-Group Shared Service Center | GP7: Ship Management-Group Shared Service Center | GR7: Vacant Seats | GS7: Vacant Seats | GT7: Vacant Seats | GU7: Vacant Seats | GV7: Vacant Seats | GW7: Vacant Seats | GX7: Vacant Seats | GY7: Vacant Seats | GZ7: Vacant Seats | HA7: Vacant Seats | HB7: Vacant Seats | HC7: Vacant Seats | HD7: Vacant Seats | HF7: Ship Management-Hamburg Dry | HG7: Ship Management-Hamburg Dry | HH7: Ship Management-Hamburg Dry | HI7: Ship Management-Hamburg Dry | HJ7: Ship Management-Hamburg Dry | HK7: Ship Management-Hamburg Dry | HL7: Ship Management-Hamburg Dry | HM7: Ship Management-Hamburg Dry | HN7: Ship Management-Hamburg Dry | HO7: Ship Management-Hamburg Dry | HP7: Ship Management-Hamburg Dry | HQ7: Ship Management-Hamburg Dry | HR7: Ship Management-Hamburg Dry | HT7: Ship Management-Hong Kong Dry 1 | HU7: Ship Management-Hong Kong Dry 1 | HV7: Ship Management-Hong Kong Dry 1 | HW7: Ship Management-Hong Kong Dry 1 | HX7: Ship Management-Hong Kong Dry 1 | HY7: Ship Management-Hong Kong Dry 1 | HZ7: Ship Management-Hong Kong Dry 1 | IA7: Ship Management-Hong Kong Dry 1 | IB7: Ship Management-Hong Kong Dry 1 | IC7: Ship Management-Hong Kong Dry 1 | ID7: Ship Management-Hong Kong Dry 1 | IE7: Ship Management-Hong Kong Dry 1 | IF7: Ship Management-Hong Kong Dry 1 | IH7: Ship Management-JV Ardmore | II7: Ship Management-JV Ardmore | IJ7: Ship Management-JV Ardmore | IK7: Ship Management-JV Ardmore | IL7: Ship Management-JV Ardmore | IM7: Ship Management-JV Ardmore | IN7: Ship Management-JV Ardmore | IO7: Ship Management-JV Ardmore | IP7: Ship Management-JV Ardmore | IQ7: Ship Management-JV Ardmore | IR7: Ship Management-JV Ardmore | IS7: Ship Management-JV Ardmore | IT7: Ship Management-JV Ardmore | IV7: Ship Management-Singapore Dry | IW7: Ship Management-Singapore Dry | IX7: Ship Management-Singapore Dry | IY7: Ship Management-Singapore Dry | IZ7: Ship Management-Singapore Dry | JA7: Ship Management-Singapore Dry | JB7: Ship Management-Singapore Dry | JC7: Ship Management-Singapore Dry | JD7: Ship Management-Singapore Dry | JE7: Ship Management-Singapore Dry | JF7: Ship Management-Singapore Dry | JG7: Ship Management-Singapore Dry | JH7: Ship Management-Singapore Dry | JJ7: Ship Management-Singapore Tanker 1 | JK7: Ship Management-Singapore Tanker 1 | JL7: Ship Management-Singapore Tanker 1 | JM7: Ship Management-Singapore Tanker 1 | JN7: Ship Management-Singapore Tanker 1 | JO7: Ship Management-Singapore Tanker 1 | JP7: Ship Management-Singapore Tanker 1 | JQ7: Ship Management-Singapore Tanker 1 | JR7: Ship Management-Singapore Tanker 1 | JS7: Ship Management-Singapore Tanker 1 | JT7: Ship Management-Singapore Tanker 1 | JU7: Ship Management-Singapore Tanker 1 | JV7: Ship Management-Singapore Tanker 1 | JX7: Ship Management-Singapore Tanker 2 | JY7: Ship Management-Singapore Tanker 2 | JZ7: Ship Management-Singapore Tanker 2 | KA7: Ship Management-Singapore Tanker 2 | KB7: Ship Management-Singapore Tanker 2 | KC7: Ship Management-Singapore Tanker 2 | KD7: Ship Management-Singapore Tanker 2 | KE7: Ship Management-Singapore Tanker 2 | KF7: Ship Management-Singapore Tanker 2 | KG7: Ship Management-Singapore Tanker 2 | KH7: Ship Management-Singapore Tanker 2 | KI7: Ship Management-Singapore Tanker 2 | KJ7: Ship Management-Singapore Tanker 2 | KL7: Accounts-Accounts Payables | KM7: Accounts-Accounts Payables | KN7: Accounts-Accounts Payables | KO7: Accounts-Accounts Payables | KP7: Accounts-Accounts Payables | KQ7: Accounts-Accounts Payables | KR7: Accounts-Accounts Payables | KS7: Accounts-Accounts Payables | KT7: Accounts-Accounts Payables | KU7: Accounts-Accounts Payables | KV7: Accounts-Accounts Payables | KW7: Accounts-Accounts Payables | KX7: Accounts-Accounts Payables | KZ7: Accounts-CMI Accounts Payables | LA7: Accounts-CMI Accounts Payables | LB7: Accounts-CMI Accounts Payables | LC7: Accounts-CMI Accounts Payables | LD7: Accounts-CMI Accounts Payables | LE7: Accounts-CMI Accounts Payables | LF7: Accounts-CMI Accounts Payables | LG7: Accounts-CMI Accounts Payables | LH7: Accounts-CMI Accounts Payables | LI7: Accounts-CMI Accounts Payables | LJ7: Accounts-CMI Accounts Payables | LK7: Accounts-CMI Accounts Payables | LL7: Accounts-CMI Accounts Payables | MB7: 30 Divisions | MC7: =MB7 -> 30 Divisions | MD7: =MC7 -> 30 Divisions | ME7: =MD7 -> 30 Divisions | MF7: =ME7 -> 30 Divisions | MG7: =MF7 -> 30 Divisions | MH7: =MG7 -> 30 Divisions | MI7: =MH7 -> 30 Divisions | MJ7: =MI7 -> 30 Divisions | ... MN7: =MM7 -> 30 Divisions
B8: INCOME
B9: Ship Management - Other Income | D9: 0 | E9: 0 | F9: 0 | G9: 0 | H9: 0 | I9: 0 | J9: 0 | K9: 0 | L9: 0 | M9: 0 | N9: 0 | O9: 0 | P9: =+SUBTOTAL(9,D9:O9) -> 0 | R9: 0 | S9: 0 | T9: 0 | U9: 0 | V9: 0 | W9: 0 | X9: 0 | Y9: 0 | Z9: 0 | AA9: 0 | AB9: 0 | AC9: 0 | AD9: =+SUBTOTAL(9,R9:AC9) -> 0 | AF9: 0 | AG9: 0 | AH9: 0 | AI9: 0 | AJ9: 0 | AK9: 0 | AL9: 0 | AM9: 0 | AN9: 0 | AO9: 0 | AP9: 0 | AQ9: 0 | AR9: =+SUBTOTAL(9,AF9:AQ9) -> 0 | AT9: 0 | AU9: 0 | AV9: 0 | AW9: 0 | AX9: 0 | AY9: 0 | AZ9: 0 | BA9: 0 | BB9: 0 | BC9: 0 | BD9: 0 | BE9: 0 | BF9: =+SUBTOTAL(9,AT9:BE9) -> 0 | BH9: 0 | BI9: 0 | BJ9: 0 | BK9: 0 | BL9: 0 | BM9: 0 | BN9: 0 | BO9: 0 | BP9: 0 | BQ9: 0 | BR9: 0 | BS9: 0 | BT9: =+SUBTOTAL(9,BH9:BS9) -> 0 | BV9: 0 | BW9: 0 | BX9: 0 | BY9: 0 | BZ9: 0 | CA9: 0 | CB9: 0 | CC9: 0 | CD9: 0 | CE9: 0 | CF9: 0 | CG9: 0 | CH9: =+SUBTOTAL(9,BV9:CG9) -> 0 | CJ9: 0 | CK9: 0 | CL9: 0 | CM9: 0 | CN9: 0 | CO9: 0 | CP9: 0 | CQ9: 0 | CR9: 0 | CS9: 0 | CT9: 0 | CU9: 0 | CV9: =+SUBTOTAL(9,CJ9:CU9) -> 0 | CX9: 0 | CY9: 0 | CZ9: 0 | DA9: 0 | DB9: 0 | DC9: 0 | DD9: 0 | DE9: 0 | DF9: 0 | DG9: 0 | DH9: 0 | DI9: 0 | DJ9: =+SUBTOTAL(9,CX9:DI9) -> 0 | DL9: 0 | DM9: 0 | DN9: 0 | DO9: 0 | DP9: 0 | DQ9: 0 | DR9: 0 | DS9: 0 | DT9: 0 | DU9: 0 | DV9: 0 | DW9: 0 | DX9: =+SUBTOTAL(9,DL9:DW9) -> 0 | DZ9: 0 | EA9: 0 | EB9: 0 | EC9: 0 | ED9: 0 | EE9: 0 | EF9: 0 | EG9: 0 | EH9: 0 | EI9: 0 | EJ9: 0 | EK9: 0 | EL9: =+SUBTOTAL(9,DZ9:EK9) -> 0 | EN9: 0 | EO9: 0 | EP9: 0 | EQ9: 0 | ER9: 0 | ES9: 0 | ET9: 0 | EU9: 0 | EV9: 0 | EW9: 0 | EX9: 0 | EY9: 0 | EZ9: =+SUBTOTAL(9,EN9:EY9) -> 0 | FB9: 0 | FC9: 0 | FD9: 0 | FE9: 0 | FF9: 0 | FG9: 0 | FH9: 0 | FI9: 0 | FJ9: 0 | FK9: 0 | FL9: 0 | FM9: 0 | FN9: =+SUBTOTAL(9,FB9:FM9) -> 0 | FP9: 0 | FQ9: 0 | FR9: 0 | FS9: 0 | FT9: 0 | FU9: 0 | FV9: 0 | FW9: 0 | FX9: 0 | FY9: 0 | FZ9: 0 | GA9: 0 | GB9: =+SUBTOTAL(9,FP9:GA9) -> 0 | GD9: 0 | GE9: 0 | GF9: 0 | GG9: 0 | GH9: 0 | GI9: 0 | GJ9: 0 | GK9: 0 | GL9: 0 | GM9: 0 | GN9: 0 | GO9: 0 | GP9: =+SUBTOTAL(9,GD9:GO9) -> 0 | GR9: 0 | GS9: 0 | GT9: 0 | GU9: 0 | GV9: 0 | GW9: 0 | GX9: 0 | GY9: 0 | GZ9: 0 | HA9: 0 | HB9: 0 | HC9: 0 | HD9: =+SUBTOTAL(9,GR9:HC9) -> 0 | HF9: 0 | HG9: 0 | HH9: 0 | HI9: 0 | HJ9: 0 | HK9: 0 | HL9: 0 | HM9: 0 | HN9: 0 | HO9: 0 | HP9: 0 | HQ9: 0 | HR9: =+SUBTOTAL(9,HF9:HQ9) -> 0 | HT9: 0 | HU9: 0 | HV9: 0 | HW9: 0 | HX9: 0 | HY9: 0 | HZ9: 0 | IA9: 0 | IB9: 0 | IC9: 0 | ID9: 0 | IE9: 0 | IF9: =+SUBTOTAL(9,HT9:IE9) -> 0 | IH9: 0 | II9: 0 | IJ9: 0 | IK9: 0 | IL9: 0 | IM9: 0 | IN9: 0 | IO9: 0 | IP9: 0 | IQ9: 0 | IR9: 0 | IS9: 0 | IT9: =+SUBTOTAL(9,IH9:IS9) -> 0 | IV9: 0 | IW9: 0 | IX9: 0 | IY9: 0 | IZ9: 0 | JA9: 0 | JB9: 0 | JC9: 0 | JD9: 0 | JE9: 0 | JF9: 0 | JG9: 0 | JH9: =+SUBTOTAL(9,IV9:JG9) -> 0 | JJ9: 0 | JK9: 0 | JL9: 0 | JM9: 0 | JN9: 0 | JO9: 0 | JP9: 0 | JQ9: 0 | JR9: 0 | JS9: 0 | JT9: 0 | JU9: 0 | JV9: =+SUBTOTAL(9,JJ9:JU9) -> 0 | JX9: 0 | JY9: 0 | JZ9: 0 | KA9: 0 | KB9: 0 | KC9: 0 | KD9: 0 | KE9: 0 | KF9: 0 | KG9: 0 | KH9: 0 | KI9: 0 | KJ9: =+SUBTOTAL(9,JX9:KI9) -> 0 | KL9: 0 | KM9: 0 | KN9: 0 | KO9: 0 | KP9: 0 | KQ9: 0 | KR9: 0 | KS9: 0 | KT9: 0 | KU9: 0 | KV9: 0 | KW9: 0 | KX9: =+SUBTOTAL(9,KL9:KW9) -> 0 | KZ9: 0 | LA9: 0 | LB9: 0 | LC9: 0 | LD9: 0 | LE9: 0 | LF9: 0 | LG9: 0 | LH9: 0 | LI9: 0 | LJ9: 0 | LK9: 0 | LL9: =+SUBTOTAL(9,KZ9:LK9) -> 0 | LN9: 0 | LO9: 0 | LP9: 0 | LQ9: 0 | LR9: 0 | LS9: 0 | LT9: 0 | LU9: 0 | LV9: 0 | LW9: 0 | LX9: 0 | LY9: 0 | LZ9: =+SUBTOTAL(9,LN9:LY9) -> 0 | MB9: =SUMIF($D$6:$LY$6,MB$3,$D9:$LY9) -> 0 | MC9: =SUMIF($D$6:$LY$6,MC$3,$D9:$LY9) -> 0 | MD9: =SUMIF($D$6:$LY$6,MD$3,$D9:$LY9) -> 0 | ME9: =SUMIF($D$6:$LY$6,ME$3,$D9:$LY9) -> 0 | MF9: =SUMIF($D$6:$LY$6,MF$3,$D9:$LY9) -> 0 | MG9: =SUMIF($D$6:$LY$6,MG$3,$D9:$LY9) -> 0 | MH9: =SUMIF($D$6:$LY$6,MH$3,$D9:$LY9) -> 0 | MI9: =SUMIF($D$6:$LY$6,MI$3,$D9:$LY9) -> 0 | ... MM9: =SUMIF($D$6:$LY$6,MM$3,$D9:$LY9) -> 0 | MN9: =SUM(MB9:MM9) -> 0
B10: Intercompany Sales | D10: 0 | E10: 0 | F10: 0 | G10: 0 | H10: 0 | I10: 0 | J10: 0 | K10: 0 | L10: 0 | M10: 0 | N10: 0 | O10: 0 | P10: =+SUBTOTAL(9,D10:O10) -> 0 | R10: 0 | S10: 0 | T10: 0 | U10: 0 | V10: 0 | W10: 0 | X10: 0 | Y10: 0 | Z10: 0 | AA10: 0 | AB10: 0 | AC10: 0 | AD10: =+SUBTOTAL(9,R10:AC10) -> 0 | AF10: 0 | AG10: 0 | AH10: 0 | AI10: 0 | AJ10: 0 | AK10: 0 | AL10: 0 | AM10: 0 | AN10: 0 | AO10: 0 | AP10: 0 | AQ10: 0 | AR10: =+SUBTOTAL(9,AF10:AQ10) -> 0 | AT10: 0 | AU10: 0 | AV10: 0 | AW10: 0 | AX10: 0 | AY10: 0 | AZ10: 0 | BA10: 0 | BB10: 0 | BC10: 0 | BD10: 0 | BE10: 0 | BF10: =+SUBTOTAL(9,AT10:BE10) -> 0 | BH10: 0 | BI10: 0 | BJ10: 0 | BK10: 0 | BL10: 0 | BM10: 0 | BN10: 0 | BO10: 0 | BP10: 0 | BQ10: 0 | BR10: 0 | BS10: 0 | BT10: =+SUBTOTAL(9,BH10:BS10) -> 0 | BV10: 0 | BW10: 0 | BX10: 0 | BY10: 0 | BZ10: 0 | CA10: 0 | CB10: 0 | CC10: 0 | CD10: 0 | CE10: 0 | CF10: 0 | CG10: 0 | CH10: =+SUBTOTAL(9,BV10:CG10) -> 0 | CJ10: 0 | CK10: 0 | CL10: 0 | CM10: 0 | CN10: 0 | CO10: 0 | CP10: 0 | CQ10: 0 | CR10: 0 | CS10: 0 | CT10: 0 | CU10: 0 | CV10: =+SUBTOTAL(9,CJ10:CU10) -> 0 | CX10: 0 | CY10: 0 | CZ10: 0 | DA10: 0 | DB10: 0 | DC10: 0 | DD10: 0 | DE10: 0 | DF10: 0 | DG10: 0 | DH10: 0 | DI10: 0 | DJ10: =+SUBTOTAL(9,CX10:DI10) -> 0 | DL10: 0 | DM10: 0 | DN10: 0 | DO10: 0 | DP10: 0 | DQ10: 0 | DR10: 0 | DS10: 0 | DT10: 0 | DU10: 0 | DV10: 0 | DW10: 0 | DX10: =+SUBTOTAL(9,DL10:DW10) -> 0 | DZ10: 0 | EA10: 0 | EB10: 0 | EC10: 0 | ED10: 0 | EE10: 0 | EF10: 0 | EG10: 0 | EH10: 0 | EI10: 0 | EJ10: 0 | EK10: 0 | EL10: =+SUBTOTAL(9,DZ10:EK10) -> 0 | EN10: 0 | EO10: 0 | EP10: 0 | EQ10: 0 | ER10: 0 | ES10: 0 | ET10: 0 | EU10: 0 | EV10: 0 | EW10: 0 | EX10: 0 | EY10: 0 | EZ10: =+SUBTOTAL(9,EN10:EY10) -> 0 | FB10: 0 | FC10: 0 | FD10: 0 | FE10: 0 | FF10: 0 | FG10: 0 | FH10: 0 | FI10: 0 | FJ10: 0 | FK10: 0 | FL10: 0 | FM10: 0 | FN10: =+SUBTOTAL(9,FB10:FM10) -> 0 | FP10: 0 | FQ10: 0 | FR10: 0 | FS10: 0 | FT10: 0 | FU10: 0 | FV10: 0 | FW10: 0 | FX10: 0 | FY10: 0 | FZ10: 0 | GA10: 0 | GB10: =+SUBTOTAL(9,FP10:GA10) -> 0 | GD10: 0 | GE10: 0 | GF10: 0 | GG10: 0 | GH10: 0 | GI10: 0 | GJ10: 0 | GK10: 0 | GL10: 0 | GM10: 0 | GN10: 0 | GO10: 0 | GP10: =+SUBTOTAL(9,GD10:GO10) -> 0 | GR10: 0 | GS10: 0 | GT10: 0 | GU10: 0 | GV10: 0 | GW10: 0 | GX10: 0 | GY10: 0 | GZ10: 0 | HA10: 0 | HB10: 0 | HC10: 0 | HD10: =+SUBTOTAL(9,GR10:HC10) -> 0 | HF10: 0 | HG10: 0 | HH10: 0 | HI10: 0 | HJ10: 0 | HK10: 0 | HL10: 0 | HM10: 0 | HN10: 0 | HO10: 0 | HP10: 0 | HQ10: 0 | HR10: =+SUBTOTAL(9,HF10:HQ10) -> 0 | HT10: 0 | HU10: 0 | HV10: 0 | HW10: 0 | HX10: 0 | HY10: 0 | HZ10: 0 | IA10: 0 | IB10: 0 | IC10: 0 | ID10: 0 | IE10: 0 | IF10: =+SUBTOTAL(9,HT10:IE10) -> 0 | IH10: 0 | II10: 0 | IJ10: 0 | IK10: 0 | IL10: 0 | IM10: 0 | IN10: 0 | IO10: 0 | IP10: 0 | IQ10: 0 | IR10: 0 | IS10: 0 | IT10: =+SUBTOTAL(9,IH10:IS10) -> 0 | IV10: 0 | IW10: 0 | IX10: 0 | IY10: 0 | IZ10: 0 | JA10: 0 | JB10: 0 | JC10: 0 | JD10: 0 | JE10: 0 | JF10: 0 | JG10: 0 | JH10: =+SUBTOTAL(9,IV10:JG10) -> 0 | JJ10: 0 | JK10: 0 | JL10: 0 | JM10: 0 | JN10: 0 | JO10: 0 | JP10: 0 | JQ10: 0 | JR10: 0 | JS10: 0 | JT10: 0 | JU10: 0 | JV10: =+SUBTOTAL(9,JJ10:JU10) -> 0 | JX10: 0 | JY10: 0 | JZ10: 0 | KA10: 0 | KB10: 0 | KC10: 0 | KD10: 0 | KE10: 0 | KF10: 0 | KG10: 0 | KH10: 0 | KI10: 0 | KJ10: =+SUBTOTAL(9,JX10:KI10) -> 0 | KL10: 0 | KM10: 0 | KN10: 0 | KO10: 0 | KP10: 0 | KQ10: 0 | KR10: 0 | KS10: 0 | KT10: 0 | KU10: 0 | KV10: 0 | KW10: 0 | KX10: =+SUBTOTAL(9,KL10:KW10) -> 0 | KZ10: 0 | LA10: 0 | LB10: 0 | LC10: 0 | LD10: 0 | LE10: 0 | LF10: 0 | LG10: 0 | LH10: 0 | LI10: 0 | LJ10: 0 | LK10: 0 | LL10: =+SUBTOTAL(9,KZ10:LK10) -> 0 | LN10: 0 | LO10: 0 | LP10: 0 | LQ10: 0 | LR10: 0 | LS10: 0 | LT10: 0 | LU10: 0 | LV10: 0 | LW10: 0 | LX10: 0 | LY10: 0 | LZ10: =+SUBTOTAL(9,LN10:LY10) -> 0 | MB10: =SUMIF($D$6:$LY$6,MB$3,$D10:$LY10) -> 0 | MC10: =SUMIF($D$6:$LY$6,MC$3,$D10:$LY10) -> 0 | MD10: =SUMIF($D$6:$LY$6,MD$3,$D10:$LY10) -> 0 | ME10: =SUMIF($D$6:$LY$6,ME$3,$D10:$LY10) -> 0 | MF10: =SUMIF($D$6:$LY$6,MF$3,$D10:$LY10) -> 0 | MG10: =SUMIF($D$6:$LY$6,MG$3,$D10:$LY10) -> 0 | MH10: =SUMIF($D$6:$LY$6,MH$3,$D10:$LY10) -> 0 | MI10: =SUMIF($D$6:$LY$6,MI$3,$D10:$LY10) -> 0 | ... MM10: =SUMIF($D$6:$LY$6,MM$3,$D10:$LY10) -> 0 | MN10: =SUM(MB10:MM10) -> 0
B12: TOTAL INCOME | D12: =SUM(D9:D11) -> 0 | E12: =SUM(E9:E11) -> 0 | F12: =SUM(F9:F11) -> 0 | G12: =SUM(G9:G11) -> 0 | H12: =SUM(H9:H11) -> 0 | I12: =SUM(I9:I11) -> 0 | J12: =SUM(J9:J11) -> 0 | K12: =SUM(K9:K11) -> 0 | ... O12: =SUM(O9:O11) -> 0 | P12: =+SUBTOTAL(9,D12:O12) -> 0 | R12: =SUM(R9:R11) -> 0 | S12: =SUM(S9:S11) -> 0 | T12: =SUM(T9:T11) -> 0 | U12: =SUM(U9:U11) -> 0 | V12: =SUM(V9:V11) -> 0 | W12: =SUM(W9:W11) -> 0 | X12: =SUM(X9:X11) -> 0 | Y12: =SUM(Y9:Y11) -> 0 | ... AC12: =SUM(AC9:AC11) -> 0 | AD12: =+SUBTOTAL(9,R12:AC12) -> 0 | AF12: =SUM(AF9:AF11) -> 0 | AG12: =SUM(AG9:AG11) -> 0 | AH12: =SUM(AH9:AH11) -> 0 | AI12: =SUM(AI9:AI11) -> 0 | AJ12: =SUM(AJ9:AJ11) -> 0 | AK12: =SUM(AK9:AK11) -> 0 | AL12: =SUM(AL9:AL11) -> 0 | AM12: =SUM(AM9:AM11) -> 0 | ... AQ12: =SUM(AQ9:AQ11) -> 0 | AR12: =+SUBTOTAL(9,AF12:AQ12) -> 0 | AT12: =SUM(AT9:AT11) -> 0 | AU12: =SUM(AU9:AU11) -> 0 | AV12: =SUM(AV9:AV11) -> 0 | AW12: =SUM(AW9:AW11) -> 0 | AX12: =SUM(AX9:AX11) -> 0 | AY12: =SUM(AY9:AY11) -> 0 | AZ12: =SUM(AZ9:AZ11) -> 0 | BA12: =SUM(BA9:BA11) -> 0 | ... BE12: =SUM(BE9:BE11) -> 0 | BF12: =+SUBTOTAL(9,AT12:BE12) -> 0 | BH12: =SUM(BH9:BH11) -> 0 | BI12: =SUM(BI9:BI11) -> 0 | BJ12: =SUM(BJ9:BJ11) -> 0 | BK12: =SUM(BK9:BK11) -> 0 | BL12: =SUM(BL9:BL11) -> 0 | BM12: =SUM(BM9:BM11) -> 0 | BN12: =SUM(BN9:BN11) -> 0 | BO12: =SUM(BO9:BO11) -> 0 | ... BS12: =SUM(BS9:BS11) -> 0 | BT12: =+SUBTOTAL(9,BH12:BS12) -> 0 | BV12: =SUM(BV9:BV11) -> 0 | BW12: =SUM(BW9:BW11) -> 0 | BX12: =SUM(BX9:BX11) -> 0 | BY12: =SUM(BY9:BY11) -> 0 | BZ12: =SUM(BZ9:BZ11) -> 0 | CA12: =SUM(CA9:CA11) -> 0 | CB12: =SUM(CB9:CB11) -> 0 | CC12: =SUM(CC9:CC11) -> 0 | ... CG12: =SUM(CG9:CG11) -> 0 | CH12: =+SUBTOTAL(9,BV12:CG12) -> 0 | CJ12: =SUM(CJ9:CJ11) -> 0 | CK12: =SUM(CK9:CK11) -> 0 | CL12: =SUM(CL9:CL11) -> 0 | CM12: =SUM(CM9:CM11) -> 0 | CN12: =SUM(CN9:CN11) -> 0 | CO12: =SUM(CO9:CO11) -> 0 | CP12: =SUM(CP9:CP11) -> 0 | CQ12: =SUM(CQ9:CQ11) -> 0 | ... CU12: =SUM(CU9:CU11) -> 0 | CV12: =+SUBTOTAL(9,CJ12:CU12) -> 0 | CX12: =SUM(CX9:CX11) -> 0 | CY12: =SUM(CY9:CY11) -> 0 | CZ12: =SUM(CZ9:CZ11) -> 0 | DA12: =SUM(DA9:DA11) -> 0 | DB12: =SUM(DB9:DB11) -> 0 | DC12: =SUM(DC9:DC11) -> 0 | DD12: =SUM(DD9:DD11) -> 0 | DE12: =SUM(DE9:DE11) -> 0 | ... DI12: =SUM(DI9:DI11) -> 0 | DJ12: =+SUBTOTAL(9,CX12:DI12) -> 0 | DL12: =SUM(DL9:DL11) -> 0 | DM12: =SUM(DM9:DM11) -> 0 | DN12: =SUM(DN9:DN11) -> 0 | DO12: =SUM(DO9:DO11) -> 0 | DP12: =SUM(DP9:DP11) -> 0 | DQ12: =SUM(DQ9:DQ11) -> 0 | DR12: =SUM(DR9:DR11) -> 0 | DS12: =SUM(DS9:DS11) -> 0 | ... DW12: =SUM(DW9:DW11) -> 0 | DX12: =+SUBTOTAL(9,DL12:DW12) -> 0 | DZ12: =SUM(DZ9:DZ11) -> 0 | EA12: =SUM(EA9:EA11) -> 0 | EB12: =SUM(EB9:EB11) -> 0 | EC12: =SUM(EC9:EC11) -> 0 | ED12: =SUM(ED9:ED11) -> 0 | EE12: =SUM(EE9:EE11) -> 0 | EF12: =SUM(EF9:EF11) -> 0 | EG12: =SUM(EG9:EG11) -> 0 | ... EK12: =SUM(EK9:EK11) -> 0 | EL12: =+SUBTOTAL(9,DZ12:EK12) -> 0 | EN12: =SUM(EN9:EN11) -> 0 | EO12: =SUM(EO9:EO11) -> 0 | EP12: =SUM(EP9:EP11) -> 0 | EQ12: =SUM(EQ9:EQ11) -> 0 | ER12: =SUM(ER9:ER11) -> 0 | ES12: =SUM(ES9:ES11) -> 0 | ET12: =SUM(ET9:ET11) -> 0 | EU12: =SUM(EU9:EU11) -> 0 | ... EY12: =SUM(EY9:EY11) -> 0 | EZ12: =+SUBTOTAL(9,EN12:EY12) -> 0 | FB12: =SUM(FB9:FB11) -> 0 | FC12: =SUM(FC9:FC11) -> 0 | FD12: =SUM(FD9:FD11) -> 0 | FE12: =SUM(FE9:FE11) -> 0 | FF12: =SUM(FF9:FF11) -> 0 | FG12: =SUM(FG9:FG11) -> 0 | FH12: =SUM(FH9:FH11) -> 0 | FI12: =SUM(FI9:FI11) -> 0 | ... FM12: =SUM(FM9:FM11) -> 0 | FN12: =+SUBTOTAL(9,FB12:FM12) -> 0 | FP12: =SUM(FP9:FP11) -> 0 | FQ12: =SUM(FQ9:FQ11) -> 0 | FR12: =SUM(FR9:FR11) -> 0 | FS12: =SUM(FS9:FS11) -> 0 | FT12: =SUM(FT9:FT11) -> 0 | FU12: =SUM(FU9:FU11) -> 0 | FV12: =SUM(FV9:FV11) -> 0 | FW12: =SUM(FW9:FW11) -> 0 | ... GA12: =SUM(GA9:GA11) -> 0 | GB12: =+SUBTOTAL(9,FP12:GA12) -> 0 | GD12: =SUM(GD9:GD11) -> 0 | GE12: =SUM(GE9:GE11) -> 0 | GF12: =SUM(GF9:GF11) -> 0 | GG12: =SUM(GG9:GG11) -> 0 | GH12: =SUM(GH9:GH11) -> 0 | GI12: =SUM(GI9:GI11) -> 0 | GJ12: =SUM(GJ9:GJ11) -> 0 | GK12: =SUM(GK9:GK11) -> 0 | ... GO12: =SUM(GO9:GO11) -> 0 | GP12: =+SUBTOTAL(9,GD12:GO12) -> 0 | GR12: =SUM(GR9:GR11) -> 0 | GS12: =SUM(GS9:GS11) -> 0 | GT12: =SUM(GT9:GT11) -> 0 | GU12: =SUM(GU9:GU11) -> 0 | GV12: =SUM(GV9:GV11) -> 0 | GW12: =SUM(GW9:GW11) -> 0 | GX12: =SUM(GX9:GX11) -> 0 | GY12: =SUM(GY9:GY11) -> 0 | ... HC12: =SUM(HC9:HC11) -> 0 | HD12: =+SUBTOTAL(9,GR12:HC12) -> 0 | HF12: =SUM(HF9:HF11) -> 0 | HG12: =SUM(HG9:HG11) -> 0 | HH12: =SUM(HH9:HH11) -> 0 | HI12: =SUM(HI9:HI11) -> 0 | HJ12: =SUM(HJ9:HJ11) -> 0 | HK12: =SUM(HK9:HK11) -> 0 | HL12: =SUM(HL9:HL11) -> 0 | HM12: =SUM(HM9:HM11) -> 0 | ... HQ12: =SUM(HQ9:HQ11) -> 0 | HR12: =+SUBTOTAL(9,HF12:HQ12) -> 0 | HT12: =SUM(HT9:HT11) -> 0 | HU12: =SUM(HU9:HU11) -> 0 | HV12: =SUM(HV9:HV11) -> 0 | HW12: =SUM(HW9:HW11) -> 0 | HX12: =SUM(HX9:HX11) -> 0 | HY12: =SUM(HY9:HY11) -> 0 | HZ12: =SUM(HZ9:HZ11) -> 0 | IA12: =SUM(IA9:IA11) -> 0 | ... IE12: =SUM(IE9:IE11) -> 0 | IF12: =+SUBTOTAL(9,HT12:IE12) -> 0 | IH12: =SUM(IH9:IH11) -> 0 | II12: =SUM(II9:II11) -> 0 | IJ12: =SUM(IJ9:IJ11) -> 0 | IK12: =SUM(IK9:IK11) -> 0 | IL12: =SUM(IL9:IL11) -> 0 | IM12: =SUM(IM9:IM11) -> 0 | IN12: =SUM(IN9:IN11) -> 0 | IO12: =SUM(IO9:IO11) -> 0 | ... IS12: =SUM(IS9:IS11) -> 0 | IT12: =+SUBTOTAL(9,IH12:IS12) -> 0 | IV12: =SUM(IV9:IV11) -> 0 | IW12: =SUM(IW9:IW11) -> 0 | IX12: =SUM(IX9:IX11) -> 0 | IY12: =SUM(IY9:IY11) -> 0 | IZ12: =SUM(IZ9:IZ11) -> 0 | JA12: =SUM(JA9:JA11) -> 0 | JB12: =SUM(JB9:JB11) -> 0 | JC12: =SUM(JC9:JC11) -> 0 | ... JG12: =SUM(JG9:JG11) -> 0 | JH12: =+SUBTOTAL(9,IV12:JG12) -> 0 | JJ12: =SUM(JJ9:JJ11) -> 0 | JK12: =SUM(JK9:JK11) -> 0 | JL12: =SUM(JL9:JL11) -> 0 | JM12: =SUM(JM9:JM11) -> 0 | JN12: =SUM(JN9:JN11) -> 0 | JO12: =SUM(JO9:JO11) -> 0 | JP12: =SUM(JP9:JP11) -> 0 | JQ12: =SUM(JQ9:JQ11) -> 0 | ... JU12: =SUM(JU9:JU11) -> 0 | JV12: =+SUBTOTAL(9,JJ12:JU12) -> 0 | JX12: =SUM(JX9:JX11) -> 0 | JY12: =SUM(JY9:JY11) -> 0 | JZ12: =SUM(JZ9:JZ11) -> 0 | KA12: =SUM(KA9:KA11) -> 0 | KB12: =SUM(KB9:KB11) -> 0 | KC12: =SUM(KC9:KC11) -> 0 | KD12: =SUM(KD9:KD11) -> 0 | KE12: =SUM(KE9:KE11) -> 0 | ... KI12: =SUM(KI9:KI11) -> 0 | KJ12: =+SUBTOTAL(9,JX12:KI12) -> 0 | KL12: =SUM(KL9:KL11) -> 0 | KM12: =SUM(KM9:KM11) -> 0 | KN12: =SUM(KN9:KN11) -> 0 | KO12: =SUM(KO9:KO11) -> 0 | KP12: =SUM(KP9:KP11) -> 0 | KQ12: =SUM(KQ9:KQ11) -> 0 | KR12: =SUM(KR9:KR11) -> 0 | KS12: =SUM(KS9:KS11) -> 0 | ... KW12: =SUM(KW9:KW11) -> 0 | KX12: =+SUBTOTAL(9,KL12:KW12) -> 0 | KZ12: =SUM(KZ9:KZ11) -> 0 | LA12: =SUM(LA9:LA11) -> 0 | LB12: =SUM(LB9:LB11) -> 0 | LC12: =SUM(LC9:LC11) -> 0 | LD12: =SUM(LD9:LD11) -> 0 | LE12: =SUM(LE9:LE11) -> 0 | LF12: =SUM(LF9:LF11) -> 0 | LG12: =SUM(LG9:LG11) -> 0 | ... LK12: =SUM(LK9:LK11) -> 0 | LL12: =+SUBTOTAL(9,KZ12:LK12) -> 0 | LN12: =SUM(LN9:LN11) -> 0 | LO12: =SUM(LO9:LO11) -> 0 | LP12: =SUM(LP9:LP11) -> 0 | LQ12: =SUM(LQ9:LQ11) -> 0 | LR12: =SUM(LR9:LR11) -> 0 | LS12: =SUM(LS9:LS11) -> 0 | LT12: =SUM(LT9:LT11) -> 0 | LU12: =SUM(LU9:LU11) -> 0 | ... LY12: =SUM(LY9:LY11) -> 0 | LZ12: =+SUBTOTAL(9,LN12:LY12) -> 0 | MB12: =SUM(MB9:MB11) -> 0 | MC12: =SUM(MC9:MC11) -> 0 | MD12: =SUM(MD9:MD11) -> 0 | ME12: =SUM(ME9:ME11) -> 0 | MF12: =SUM(MF9:MF11) -> 0 | MG12: =SUM(MG9:MG11) -> 0 | MH12: =SUM(MH9:MH11) -> 0 | MI12: =SUM(MI9:MI11) -> 0 | ... MN12: =SUM(MN9:MN11) -> 0
B14: DIRECT COSTS
B15: Crew Management | D15: 0 | E15: 0 | F15: 0 | G15: 0 | H15: 0 | I15: 0 | J15: 0 | K15: 0 | L15: 0 | M15: 0 | N15: 0 | O15: 0 | P15: =+SUBTOTAL(9,D15:O15) -> 0 | R15: 0 | S15: 0 | T15: 0 | U15: 0 | V15: 0 | W15: 0 | X15: 0 | Y15: 0 | Z15: 0 | AA15: 0 | AB15: 0 | AC15: 0 | AD15: =+SUBTOTAL(9,R15:AC15) -> 0 | AF15: 0 | AG15: 0 | AH15: 0 | AI15: 0 | AJ15: 0 | AK15: 0 | AL15: 0 | AM15: 0 | AN15: 0 | AO15: 0 | AP15: 0 | AQ15: 0 | AR15: =+SUBTOTAL(9,AF15:AQ15) -> 0 | AT15: 0 | AU15: 0 | AV15: 0 | AW15: 0 | AX15: 0 | AY15: 0 | AZ15: 0 | BA15: 0 | BB15: 0 | BC15: 0 | BD15: 0 | BE15: 0 | BF15: =+SUBTOTAL(9,AT15:BE15) -> 0 | BH15: 0 | BI15: 0 | BJ15: 0 | BK15: 0 | BL15: 0 | BM15: 0 | BN15: 0 | BO15: 0 | BP15: 0 | BQ15: 0 | BR15: 0 | BS15: 0 | BT15: =+SUBTOTAL(9,BH15:BS15) -> 0 | BV15: 0 | BW15: 0 | BX15: 0 | BY15: 0 | BZ15: 0 | CA15: 0 | CB15: 0 | CC15: 0 | CD15: 0 | CE15: 0 | CF15: 0 | CG15: 0 | CH15: =+SUBTOTAL(9,BV15:CG15) -> 0 | CJ15: 0 | CK15: 0 | CL15: 0 | CM15: 0 | CN15: 0 | CO15: 0 | CP15: 0 | CQ15: 0 | CR15: 0 | CS15: 0 | CT15: 0 | CU15: 0 | CV15: =+SUBTOTAL(9,CJ15:CU15) -> 0 | CX15: 0 | CY15: 0 | CZ15: 0 | DA15: 0 | DB15: 0 | DC15: 0 | DD15: 0 | DE15: 0 | DF15: 0 | DG15: 0 | DH15: 0 | DI15: 0 | DJ15: =+SUBTOTAL(9,CX15:DI15) -> 0 | DL15: 0 | DM15: 0 | DN15: 0 | DO15: 0 | DP15: 0 | DQ15: 0 | DR15: 0 | DS15: 0 | DT15: 0 | DU15: 0 | DV15: 0 | DW15: 0 | DX15: =+SUBTOTAL(9,DL15:DW15) -> 0 | DZ15: 0 | EA15: 0 | EB15: 0 | EC15: 0 | ED15: 0 | EE15: 0 | EF15: 0 | EG15: 0 | EH15: 0 | EI15: 0 | EJ15: 0 | EK15: 0 | EL15: =+SUBTOTAL(9,DZ15:EK15) -> 0 | EN15: 0 | EO15: 0 | EP15: 0 | EQ15: 0 | ER15: 0 | ES15: 0 | ET15: 0 | EU15: 0 | EV15: 0 | EW15: 0 | EX15: 0 | EY15: 0 | EZ15: =+SUBTOTAL(9,EN15:EY15) -> 0 | FB15: 0 | FC15: 0 | FD15: 0 | FE15: 0 | FF15: 0 | FG15: 0 | FH15: 0 | FI15: 0 | FJ15: 0 | FK15: 0 | FL15: 0 | FM15: 0 | FN15: =+SUBTOTAL(9,FB15:FM15) -> 0 | FP15: 0 | FQ15: 0 | FR15: 0 | FS15: 0 | FT15: 0 | FU15: 0 | FV15: 0 | FW15: 0 | FX15: 0 | FY15: 0 | FZ15: 0 | GA15: 0 | GB15: =+SUBTOTAL(9,FP15:GA15) -> 0 | GD15: 0 | GE15: 0 | GF15: 0 | GG15: 0 | GH15: 0 | GI15: 0 | GJ15: 0 | GK15: 0 | GL15: 0 | GM15: 0 | GN15: 0 | GO15: 0 | GP15: =+SUBTOTAL(9,GD15:GO15) -> 0 | GR15: 0 | GS15: 0 | GT15: 0 | GU15: 0 | GV15: 0 | GW15: 0 | GX15: 0 | GY15: 0 | GZ15: 0 | HA15: 0 | HB15: 0 | HC15: 0 | HD15: =+SUBTOTAL(9,GR15:HC15) -> 0 | HF15: 0 | HG15: 0 | HH15: 0 | HI15: 0 | HJ15: 0 | HK15: 0 | HL15: 0 | HM15: 0 | HN15: 0 | HO15: 0 | HP15: 0 | HQ15: 0 | HR15: =+SUBTOTAL(9,HF15:HQ15) -> 0 | HT15: 0 | HU15: 0 | HV15: 0 | HW15: 0 | HX15: 0 | HY15: 0 | HZ15: 0 | IA15: 0 | IB15: 0 | IC15: 0 | ID15: 0 | IE15: 0 | IF15: =+SUBTOTAL(9,HT15:IE15) -> 0 | IH15: 0 | II15: 0 | IJ15: 0 | IK15: 0 | IL15: 0 | IM15: 0 | IN15: 0 | IO15: 0 | IP15: 0 | IQ15: 0 | IR15: 0 | IS15: 0 | IT15: =+SUBTOTAL(9,IH15:IS15) -> 0 | IV15: 0 | IW15: 0 | IX15: 0 | IY15: 0 | IZ15: 0 | JA15: 0 | JB15: 0 | JC15: 0 | JD15: 0 | JE15: 0 | JF15: 0 | JG15: 0 | JH15: =+SUBTOTAL(9,IV15:JG15) -> 0 | JJ15: 0 | JK15: 0 | JL15: 0 | JM15: 0 | JN15: 0 | JO15: 0 | JP15: 0 | JQ15: 0 | JR15: 0 | JS15: 0 | JT15: 0 | JU15: 0 | JV15: =+SUBTOTAL(9,JJ15:JU15) -> 0 | JX15: 0 | JY15: 0 | JZ15: 0 | KA15: 0 | KB15: 0 | KC15: 0 | KD15: 0 | KE15: 0 | KF15: 0 | KG15: 0 | KH15: 0 | KI15: 0 | KJ15: =+SUBTOTAL(9,JX15:KI15) -> 0 | KL15: 0 | KM15: 0 | KN15: 0 | KO15: 0 | KP15: 0 | KQ15: 0 | KR15: 0 | KS15: 0 | KT15: 0 | KU15: 0 | KV15: 0 | KW15: 0 | KX15: =+SUBTOTAL(9,KL15:KW15) -> 0 | KZ15: 0 | LA15: 0 | LB15: 0 | LC15: 0 | LD15: 0 | LE15: 0 | LF15: 0 | LG15: 0 | LH15: 0 | LI15: 0 | LJ15: 0 | LK15: 0 | LL15: =+SUBTOTAL(9,KZ15:LK15) -> 0 | LN15: 0 | LO15: 0 | LP15: 0 | LQ15: 0 | LR15: 0 | LS15: 0 | LT15: 0 | LU15: 0 | LV15: 0 | LW15: 0 | LX15: 0 | LY15: 0 | LZ15: =+SUBTOTAL(9,LN15:LY15) -> 0 | MB15: =SUMIF($D$6:$LY$6,MB$3,$D15:$LY15) -> 0 | MC15: =SUMIF($D$6:$LY$6,MC$3,$D15:$LY15) -> 0 | MD15: =SUMIF($D$6:$LY$6,MD$3,$D15:$LY15) -> 0 | ME15: =SUMIF($D$6:$LY$6,ME$3,$D15:$LY15) -> 0 | MF15: =SUMIF($D$6:$LY$6,MF$3,$D15:$LY15) -> 0 | MG15: =SUMIF($D$6:$LY$6,MG$3,$D15:$LY15) -> 0 | MH15: =SUMIF($D$6:$LY$6,MH$3,$D15:$LY15) -> 0 | MI15: =SUMIF($D$6:$LY$6,MI$3,$D15:$LY15) -> 0 | ... MM15: =SUMIF($D$6:$LY$6,MM$3,$D15:$LY15) -> 0 | MN15: =SUM(MB15:MM15) -> 0
